Workbook

Sheet 1월
D6: =G6+M6+N6 | G6: =SUM(H6:L6) | H6: =SUM(H7:H11) | I6: =SUM(I7:I11) | J6: =SUM(J7:J11) | K6: =SUM(K7:K11) | L6: =SUM(L7:L11) | M6: =SUM(M7:M11) | N6: =SUM(O6:U6) | O6: =SUM(O7:O11) | P6: =SUM(P7:P11) | Q6: =SUM(Q7:Q11) | R6: =SUM(R7:R11) | S6: =SUM(S7:S11) | T6: =SUM(T7:T11) | U6: =SUM(U7:U11)
D7: =G7+M7+N7 | G7: =SUM(H7:L7) | N7: =SUM(O7:U7)
D8: =G8+M8+N8 | G8: =SUM(H8:L8) | N8: =SUM(O8:U8)
D9: =G9+M9+N9 | G9: =SUM(H9:L9) | N9: =SUM(O9:U9)
D10: =G10+M10+N10 | G10: =SUM(H10:L10) | N10: =SUM(O10:U10)
D11: =G11+M11+N11 | G11: =SUM(H11:L11) | H11: =SUM(H12:H15) | I11: =SUM(I12:I15) | J11: =SUM(J12:J15) | K11: =SUM(K12:K15) | L11: =SUM(L12:L15) | M11: =SUM(M12:M15) | N11: =SUM(O11:U11) | O11: =SUM(O12:O15) | P11: =SUM(P12:P15) | Q11: =SUM(Q12:Q15) | R11: =SUM(R12:R15) | S11: =SUM(S12:S15) | T11: =SUM(T12:T15) | U11: =SUM(U12:U15)
D12: =G12+M12+N12 | G12: =SUM(H12:L12) | N12: =SUM(O12:U12)
D13: =G13+M13+N13 | G13: =SUM(H13:L13) | N13: =SUM(O13:U13)
D14: =G14+M14+N14 | G14: =SUM(H14:L14) | N14: =SUM(O14:U14)
D15: =G15+M15+N15 | G15: =SUM(H15:L15) | N15: =SUM(O15:U15)
D16: =G16+M16+N16 | G16: =SUM(H16:L16) | H16: =SUM(H17:H28) | I16: =SUM(I17:I28) | J16: =SUM(J17:J28) | K16: =SUM(K17:K28) | L16: =SUM(L17:L28) | M16: =SUM(M17:M28) | N16: =SUM(O16:U16) | O16: =SUM(O17:O28) | P16: =SUM(P17:P28) | Q16: =SUM(Q17:Q28) | R16: =SUM(R17:R28) | S16: =SUM(S17:S28) | T16: =SUM(T17:T28) | U16: =SUM(U17:U28)
D17: =G17+M17+N17 | G17: =SUM(H17:L17) | N17: =SUM(O17:U17)
D18: =G18+M18+N18 | G18: =SUM(H18:L18) | N18: =SUM(O18:U18)
D19: =G19+M19+N19 | G19: =SUM(H19:L19) | N19: =SUM(O19:U19)
D20: =G20+M20+N20 | G20: =SUM(H20:L20) | N20: =SUM(O20:U20)
D21: =G21+M21+N21 | G21: =SUM(H21:L21) | N21: =SUM(O21:U21)
D22: =G22+M22+N22 | G22: =SUM(H22:L22) | N22: =SUM(O22:U22)
D23: =G23+M23+N23 | G23: =SUM(H23:L23) | N23: =SUM(O23:U23)
D24: =G24+M24+N24 | G24: =SUM(H24:L24) | N24: =SUM(O24:U24)
D25: =G25+M25+N25 | G25: =SUM(H25:L25) | N25: =SUM(O25:U25)
D26: =G26+M26+N26 | G26: =SUM(H26:L26) | N26: =SUM(O26:U26)
D27: =G27+M27+N27 | G27: =SUM(H27:L27) | N27: =SUM(O27:U27)
D28: =G28+M28+N28 | G28: =SUM(H28:L28) | N28: =SUM(O28:U28)
D29: =G29+M29+N29 | G29: =SUM(H29:L29) | H29: =H6+H16 | I29: =I6+I16 | J29: =J6+J16 | K29: =K6+K16 | L29: =L6+L16 | M29: =M6+M16 | N29: =SUM(O29:U29) | O29: =O6+O16 | P29: =P6+P16 | Q29: =Q6+Q16 | R29: =R6+R16 | S29: =S6+S16 | T29: =T6+T16 | U29: =U6+U16
C36: =D6 | D36: =G36+M36+N36 | E36: =D36-C36 | F36: =IFERROR(D36/C36,0) | G36: =SUM(H36:L36) | H36: =SUM(H37:H41) | I36: =SUM(I37:I41) | J36: =SUM(J37:J41) | K36: =SUM(K37:K41) | L36: =SUM(L37:L41) | M36: =SUM(M37:M41) | N36: =SUM(O36:U36) | O36: =SUM(O37:O41) | P36: =SUM(P37:P41) | Q36: =SUM(Q37:Q41) | R36: =SUM(R37:R41) | S36: =SUM(S37:S41) | T36: =SUM(T37:T41) | U36: =SUM(U37:U41)
D37: =G37+M37+N37 | E37: =D37-C37 | F37: =IFERROR(D37/C37,"") | G37: =SUM(H37:L37) | N37: =SUM(O37:U37)
D38: =G38+M38+N38 | E38: =D38-C38 | F38: =IFERROR(D38/C38,"") | G38: =SUM(H38:L38) | N38: =SUM(O38:U38)
D39: =G39+M39+N39 | E39: =D39-C39 | F39: =IFERROR(D39/C39,"") | G39: =SUM(H39:L39) | N39: =SUM(O39:U39)
D40: =G40+M40+N40 | E40: =D40-C40 | F40: =IFERROR(D40/C40,"") | G40: =SUM(H40:L40) | N40: =SUM(O40:U40)
D41: =G41+M41+N41 | E41: =D41-C41 | F41: =IFERROR(D41/C41,"") | G41: =SUM(H41:L41) | N41: =SUM(O41:U41) | T41: =SUM(T42:T45) | U41: =SUM(U42:U45)
C42: =D12 | D42: =G42+M42+N42 | E42: =D42-C42 | F42: =IFERROR(D42/C42,0) | G42: =SUM(H42:L42) | N42: =SUM(O42:U42)
C43: =D13 | D43: =G43+M43+N43 | E43: =D43-C43 | F43: =IFERROR(D43/C43,0) | G43: =SUM(H43:L43) | N43: =SUM(O43:U43)
C44: =D14 | D44: =G44+M44+N44 | E44: =D44-C44 | F44: =IFERROR(D44/C44,0) | G44: =SUM(H44:L44) | N44: =SUM(O44:U44)
C45: =D15 | D45: =G45+M45+N45 | E45: =D45-C45 | F45: =IFERROR(D45/C45,0) | G45: =SUM(H45:L45) | N45: =SUM(O45:U45)
C46: =D16 | D46: =G46+M46+N46 | E46: =D46-C46 | F46: =IFERROR(D46/C46,0) | G46: =SUM(H46:L46) | H46: =SUM(H47:H58) | I46: =SUM(I47:I58) | J46: =SUM(J47:J58) | K46: =SUM(K47:K58) | L46: =SUM(L47:L58) | M46: =SUM(M47:M58) | N46: =SUM(O46:U46) | O46: =SUM(O47:O58) | P46: =SUM(P47:P58) | Q46: =SUM(Q47:Q58) | R46: =SUM(R47:R58) | S46: =SUM(S47:S58) | T46: =SUM(T47:T58) | U46: =SUM(U47:U58)
D47: =G47+M47+N47 | E47: =D47-C47 | F47: =IFERROR(D47/C47,"") | G47: =SUM(H47:L47) | N47: =SUM(O47:U47)
D48: =G48+M48+N48 | E48: =D48-C48 | F48: =IFERROR(D48/C48,"") | G48: =SUM(H48:L48) | N48: =SUM(O48:U48)
D49: =G49+M49+N49 | E49: =D49-C49 | F49: =IFERROR(D49/C49,"") | G49: =SUM(H49:L49) | N49: =SUM(O49:U49)
D50: =G50+M50+N50 | E50: =D50-C50 | F50: =IFERROR(D50/C50,"") | G50: =SUM(H50:L50) | N50: =SUM(O50:U50)
D51: =G51+M51+N51 | E51: =D51-C51 | F51: =IFERROR(D51/C51,"") | G51: =SUM(H51:L51) | N51: =SUM(O51:U51)
...

Sheet 2월
D6: =G6+M6+N6 | G6: =SUM(H6:L6) | H6: =SUM(H7:H11) | I6: =SUM(I7:I11) | J6: =SUM(J7:J11) | K6: =SUM(K7:K11) | L6: =SUM(L7:L11) | M6: =SUM(M7:M11) | N6: =SUM(O6:U6) | O6: =SUM(O7:O11) | P6: =SUM(P7:P11) | Q6: =SUM(Q7:Q11) | R6: =SUM(R7:R11) | S6: =SUM(S7:S11) | T6: =SUM(T7:T11) | U6: =SUM(U7:U11)
D7: =G7+M7+N7 | G7: =SUM(H7:L7) | N7: =SUM(O7:U7)
D8: =G8+M8+N8 | G8: =SUM(H8:L8) | N8: =SUM(O8:U8)
D9: =G9+M9+N9 | G9: =SUM(H9:L9) | N9: =SUM(O9:U9)
D10: =G10+M10+N10 | G10: =SUM(H10:L10) | N10: =SUM(O10:U10)
D11: =G11+M11+N11 | G11: =SUM(H11:L11) | H11: =SUM(H12:H15) | I11: =SUM(I12:I15) | J11: =SUM(J12:J15) | K11: =SUM(K12:K15) | L11: =SUM(L12:L15) | M11: =SUM(M12:M15) | N11: =SUM(O11:U11) | O11: =SUM(O12:O15) | P11: =SUM(P12:P15) | Q11: =SUM(Q12:Q15) | R11: =SUM(R12:R15) | S11: =SUM(S12:S15) | T11: =SUM(T12:T15) | U11: =SUM(U12:U15)
D12: =G12+M12+N12 | G12: =SUM(H12:L12) | N12: =SUM(O12:U12)
D13: =G13+M13+N13 | G13: =SUM(H13:L13) | N13: =SUM(O13:U13)
D14: =G14+M14+N14 | G14: =SUM(H14:L14) | N14: =SUM(O14:U14)
D15: =G15+M15+N15 | G15: =SUM(H15:L15) | N15: =SUM(O15:U15)
D16: =G16+M16+N16 | G16: =SUM(H16:L16) | H16: =SUM(H17:H28) | I16: =SUM(I17:I28) | J16: =SUM(J17:J28) | K16: =SUM(K17:K28) | L16: =SUM(L17:L28) | M16: =SUM(M17:M28) | N16: =SUM(O16:U16) | O16: =SUM(O17:O28) | P16: =SUM(P17:P28) | Q16: =SUM(Q17:Q28) | R16: =SUM(R17:R28) | S16: =SUM(S17:S28) | T16: =SUM(T17:T28) | U16: =SUM(U17:U28)
D17: =G17+M17+N17 | G17: =SUM(H17:L17) | N17: =SUM(O17:U17)
D18: =G18+M18+N18 | G18: =SUM(H18:L18) | N18: =SUM(O18:U18)
D19: =G19+M19+N19 | G19: =SUM(H19:L19) | N19: =SUM(O19:U19)
D20: =G20+M20+N20 | G20: =SUM(H20:L20) | N20: =SUM(O20:U20)
D21: =G21+M21+N21 | G21: =SUM(H21:L21) | N21: =SUM(O21:U21)
D22: =G22+M22+N22 | G22: =SUM(H22:L22) | N22: =SUM(O22:U22)
D23: =G23+M23+N23 | G23: =SUM(H23:L23) | N23: =SUM(O23:U23)
D24: =G24+M24+N24 | G24: =SUM(H24:L24) | N24: =SUM(O24:U24)
D25: =G25+M25+N25 | G25: =SUM(H25:L25) | N25: =SUM(O25:U25)
D26: =G26+M26+N26 | G26: =SUM(H26:L26) | N26: =SUM(O26:U26)
D27: =G27+M27+N27 | G27: =SUM(H27:L27) | N27: =SUM(O27:U27)
D28: =G28+M28+N28 | G28: =SUM(H28:L28) | N28: =SUM(O28:U28)
D29: =G29+M29+N29 | G29: =SUM(H29:L29) | H29: =H6+H16 | I29: =I6+I16 | J29: =J6+J16 | K29: =K6+K16 | L29: =L6+L16 | M29: =M6+M16 | N29: =SUM(O29:U29) | O29: =O6+O16 | P29: =P6+P16 | Q29: =Q6+Q16 | R29: =R6+R16 | S29: =S6+S16 | T29: =T6+T16 | U29: =U6+U16
C36: =D6 | D36: =G36+M36+N36 | E36: =D36-C36 | F36: =IFERROR(D36/C36,0) | G36: =SUM(H36:L36) | H36: =SUM(H37:H41) | I36: =SUM(I37:I41) | J36: =SUM(J37:J41) | K36: =SUM(K37:K41) | L36: =SUM(L37:L41) | M36: =SUM(M37:M41) | N36: =SUM(O36:U36) | O36: =SUM(O37:O41) | P36: =SUM(P37:P41) | Q36: =SUM(Q37:Q41) | R36: =SUM(R37:R41) | S36: =SUM(S37:S41) | T36: =SUM(T37:T41) | U36: =SUM(U37:U41)
D37: =G37+M37+N37 | E37: =D37-C37 | F37: =IFERROR(D37/C37,"") | G37: =SUM(H37:L37) | N37: =SUM(O37:U37)
D38: =G38+M38+N38 | E38: =D38-C38 | F38: =IFERROR(D38/C38,"") | G38: =SUM(H38:L38) | N38: =SUM(O38:U38)
D39: =G39+M39+N39 | E39: =D39-C39 | F39: =IFERROR(D39/C39,"") | G39: =SUM(H39:L39) | N39: =SUM(O39:U39)
D40: =G40+M40+N40 | E40: =D40-C40 | F40: =IFERROR(D40/C40,"") | G40: =SUM(H40:L40) | N40: =SUM(O40:U40)
D41: =G41+M41+N41 | E41: =D41-C41 | F41: =IFERROR(D41/C41,"") | G41: =SUM(H41:L41) | N41: =SUM(O41:U41) | T41: =SUM(T42:T45) | U41: =SUM(U42:U45)
C42: =D12 | D42: =G42+M42+N42 | E42: =D42-C42 | F42: =IFERROR(D42/C42,0) | G42: =SUM(H42:L42) | N42: =SUM(O42:U42)
C43: =D13 | D43: =G43+M43+N43 | E43: =D43-C43 | F43: =IFERROR(D43/C43,0) | G43: =SUM(H43:L43) | N43: =SUM(O43:U43)
C44: =D14 | D44: =G44+M44+N44 | E44: =D44-C44 | F44: =IFERROR(D44/C44,0) | G44: =SUM(H44:L44) | N44: =SUM(O44:U44)
C45: =D15 | D45: =G45+M45+N45 | E45: =D45-C45 | F45: =IFERROR(D45/C45,0) | G45: =SUM(H45:L45) | N45: =SUM(O45:U45)
C46: =D16 | D46: =G46+M46+N46 | E46: =D46-C46 | F46: =IFERROR(D46/C46,0) | G46: =SUM(H46:L46) | H46: =SUM(H47:H58) | I46: =SUM(I47:I58) | J46: =SUM(J47:J58) | K46: =SUM(K47:K58) | L46: =SUM(L47:L58) | M46: =SUM(M47:M58) | N46: =SUM(O46:U46) | O46: =SUM(O47:O58) | P46: =SUM(P47:P58) | Q46: =SUM(Q47:Q58) | R46: =SUM(R47:R58) | S46: =SUM(S47:S58) | T46: =SUM(T47:T58) | U46: =SUM(U47:U58)
D47: =G47+M47+N47 | E47: =D47-C47 | F47: =IFERROR(D47/C47,"") | G47: =SUM(H47:L47) | N47: =SUM(O47:U47)
D48: =G48+M48+N48 | E48: =D48-C48 | F48: =IFERROR(D48/C48,"") | G48: =SUM(H48:L48) | N48: =SUM(O48:U48)
D49: =G49+M49+N49 | E49: =D49-C49 | F49: =IFERROR(D49/C49,"") | G49: =SUM(H49:L49) | N49: =SUM(O49:U49)
D50: =G50+M50+N50 | E50: =D50-C50 | F50: =IFERROR(D50/C50,"") | G50: =SUM(H50:L50) | N50: =SUM(O50:U50)
D51: =G51+M51+N51 | E51: =D51-C51 | F51: =IFERROR(D51/C51,"") | G51: =SUM(H51:L51) | N51: =SUM(O51:U51)
...

Sheet 2월 누계
D6: =G6+M6+N6 | G6: =SUM(H6:L6) | H6: =SUM(H7:H11) | I6: =SUM(I7:I11) | J6: =SUM(J7:J11) | K6: =SUM(K7:K11) | L6: =SUM(L7:L11) | M6: =SUM(M7:M11) | N6: =SUM(O6:U6) | O6: =SUM(O7:O11) | P6: =SUM(P7:P11) | Q6: =SUM(Q7:Q11) | R6: =SUM(R7:R11) | S6: =SUM(S7:S11) | T6: =SUM(T7:T11) | U6: =SUM(U7:U11)
D7: =G7+M7+N7 | G7: =SUM(H7:L7) | H7: ='1월'!H7+'2월'!H7 | I7: ='1월'!I7+'2월'!I7 | J7: ='1월'!J7+'2월'!J7 | K7: ='1월'!K7+'2월'!K7 | L7: ='1월'!L7+'2월'!L7 | M7: ='1월'!M7+'2월'!M7 | N7: =SUM(O7:U7) | O7: ='1월'!O7+'2월'!O7 | P7: ='1월'!P7+'2월'!P7 | Q7: ='1월'!Q7+'2월'!Q7 | R7: ='1월'!R7+'2월'!R7 | S7: ='1월'!S7+'2월'!S7 | T7: ='1월'!T7+'2월'!T7 | U7: ='1월'!U7+'2월'!U7
D8: =G8+M8+N8 | G8: =SUM(H8:L8) | H8: ='1월'!H8+'2월'!H8 | I8: ='1월'!I8+'2월'!I8 | J8: ='1월'!J8+'2월'!J8 | K8: ='1월'!K8+'2월'!K8 | L8: ='1월'!L8+'2월'!L8 | M8: ='1월'!M8+'2월'!M8 | N8: =SUM(O8:U8) | O8: ='1월'!O8+'2월'!O8 | P8: ='1월'!P8+'2월'!P8 | Q8: ='1월'!Q8+'2월'!Q8 | R8: ='1월'!R8+'2월'!R8 | S8: ='1월'!S8+'2월'!S8 | T8: ='1월'!T8+'2월'!T8 | U8: ='1월'!U8+'2월'!U8
D9: =G9+M9+N9 | G9: =SUM(H9:L9) | H9: ='1월'!H9+'2월'!H9 | I9: ='1월'!I9+'2월'!I9 | J9: ='1월'!J9+'2월'!J9 | K9: ='1월'!K9+'2월'!K9 | L9: ='1월'!L9+'2월'!L9 | M9: ='1월'!M9+'2월'!M9 | N9: =SUM(O9:U9) | O9: ='1월'!O9+'2월'!O9 | P9: ='1월'!P9+'2월'!P9 | Q9: ='1월'!Q9+'2월'!Q9 | R9: ='1월'!R9+'2월'!R9 | S9: ='1월'!S9+'2월'!S9 | T9: ='1월'!T9+'2월'!T9 | U9: ='1월'!U9+'2월'!U9
D10: =G10+M10+N10 | G10: =SUM(H10:L10) | H10: ='1월'!H10+'2월'!H10 | I10: ='1월'!I10+'2월'!I10 | J10: ='1월'!J10+'2월'!J10 | K10: ='1월'!K10+'2월'!K10 | L10: ='1월'!L10+'2월'!L10 | M10: ='1월'!M10+'2월'!M10 | N10: =SUM(O10:U10) | O10: ='1월'!O10+'2월'!O10 | P10: ='1월'!P10+'2월'!P10 | Q10: ='1월'!Q10+'2월'!Q10 | R10: ='1월'!R10+'2월'!R10 | S10: ='1월'!S10+'2월'!S10 | T10: ='1월'!T10+'2월'!T10 | U10: ='1월'!U10+'2월'!U10
D11: =G11+M11+N11 | G11: =SUM(H11:L11) | H11: =SUM(H12:H15) | I11: =SUM(I12:I15) | J11: =SUM(J12:J15) | K11: =SUM(K12:K15) | L11: =SUM(L12:L15) | M11: =SUM(M12:M15) | N11: =SUM(O11:U11) | O11: =SUM(O12:O15) | P11: =SUM(P12:P15) | Q11: =SUM(Q12:Q15) | R11: =SUM(R12:R15) | S11: =SUM(S12:S15) | T11: =SUM(T12:T15) | U11: =SUM(U12:U15)
D12: =G12+M12+N12 | G12: =SUM(H12:L12) | H12: ='1월'!H12+'2월'!H12 | I12: ='1월'!I12+'2월'!I12 | J12: ='1월'!J12+'2월'!J12 | K12: ='1월'!K12+'2월'!K12 | L12: ='1월'!L12+'2월'!L12 | M12: ='1월'!M12+'2월'!M12 | N12: =SUM(O12:U12) | O12: ='1월'!O12+'2월'!O12 | P12: ='1월'!P12+'2월'!P12 | Q12: ='1월'!Q12+'2월'!Q12 | R12: ='1월'!R12+'2월'!R12 | S12: ='1월'!S12+'2월'!S12 | T12: ='1월'!T12+'2월'!T12 | U12: ='1월'!U12+'2월'!U12
D13: =G13+M13+N13 | G13: =SUM(H13:L13) | H13: ='1월'!H13+'2월'!H13 | I13: ='1월'!I13+'2월'!I13 | J13: ='1월'!J13+'2월'!J13 | K13: ='1월'!K13+'2월'!K13 | L13: ='1월'!L13+'2월'!L13 | M13: ='1월'!M13+'2월'!M13 | N13: =SUM(O13:U13) | O13: ='1월'!O13+'2월'!O13 | P13: ='1월'!P13+'2월'!P13 | Q13: ='1월'!Q13+'2월'!Q13 | R13: ='1월'!R13+'2월'!R13 | S13: ='1월'!S13+'2월'!S13 | T13: ='1월'!T13+'2월'!T13 | U13: ='1월'!U13+'2월'!U13
D14: =G14+M14+N14 | G14: =SUM(H14:L14) | H14: ='1월'!H14+'2월'!H14 | I14: ='1월'!I14+'2월'!I14 | J14: ='1월'!J14+'2월'!J14 | K14: ='1월'!K14+'2월'!K14 | L14: ='1월'!L14+'2월'!L14 | M14: ='1월'!M14+'2월'!M14 | N14: =SUM(O14:U14) | O14: ='1월'!O14+'2월'!O14 | P14: ='1월'!P14+'2월'!P14 | Q14: ='1월'!Q14+'2월'!Q14 | R14: ='1월'!R14+'2월'!R14 | S14: ='1월'!S14+'2월'!S14 | T14: ='1월'!T14+'2월'!T14 | U14: ='1월'!U14+'2월'!U14
D15: =G15+M15+N15 | G15: =SUM(H15:L15) | H15: ='1월'!H15+'2월'!H15 | I15: ='1월'!I15+'2월'!I15 | J15: ='1월'!J15+'2월'!J15 | K15: ='1월'!K15+'2월'!K15 | L15: ='1월'!L15+'2월'!L15 | M15: ='1월'!M15+'2월'!M15 | N15: =SUM(O15:U15) | O15: ='1월'!O15+'2월'!O15 | P15: ='1월'!P15+'2월'!P15 | Q15: ='1월'!Q15+'2월'!Q15 | R15: ='1월'!R15+'2월'!R15 | S15: ='1월'!S15+'2월'!S15 | T15: ='1월'!T15+'2월'!T15 | U15: ='1월'!U15+'2월'!U15
D16: =G16+M16+N16 | G16: =SUM(H16:L16) | H16: =SUM(H17:H28) | I16: =SUM(I17:I28) | J16: =SUM(J17:J28) | K16: =SUM(K17:K28) | L16: =SUM(L17:L28) | M16: =SUM(M17:M28) | N16: =SUM(O16:U16) | O16: =SUM(O17:O28) | P16: =SUM(P17:P28) | Q16: =SUM(Q17:Q28) | R16: =SUM(R17:R28) | S16: =SUM(S17:S28) | T16: =SUM(T17:T28) | U16: =SUM(U17:U28)
D17: =G17+M17+N17 | G17: =SUM(H17:L17) | H17: ='1월'!H17+'2월'!H17 | I17: ='1월'!I17+'2월'!I17 | J17: ='1월'!J17+'2월'!J17 | K17: ='1월'!K17+'2월'!K17 | L17: ='1월'!L17+'2월'!L17 | M17: ='1월'!M17+'2월'!M17 | N17: =SUM(O17:U17) | O17: ='1월'!O17+'2월'!O17 | P17: ='1월'!P17+'2월'!P17 | Q17: ='1월'!Q17+'2월'!Q17 | R17: ='1월'!R17+'2월'!R17 | S17: ='1월'!S17+'2월'!S17 | T17: ='1월'!T17+'2월'!T17 | U17: ='1월'!U17+'2월'!U17
D18: =G18+M18+N18 | G18: =SUM(H18:L18) | H18: ='1월'!H18+'2월'!H18 | I18: ='1월'!I18+'2월'!I18 | J18: ='1월'!J18+'2월'!J18 | K18: ='1월'!K18+'2월'!K18 | L18: ='1월'!L18+'2월'!L18 | M18: ='1월'!M18+'2월'!M18 | N18: =SUM(O18:U18) | O18: ='1월'!O18+'2월'!O18 | P18: ='1월'!P18+'2월'!P18 | Q18: ='1월'!Q18+'2월'!Q18 | R18: ='1월'!R18+'2월'!R18 | S18: ='1월'!S18+'2월'!S18 | T18: ='1월'!T18+'2월'!T18 | U18: ='1월'!U18+'2월'!U18
D19: =G19+M19+N19 | G19: =SUM(H19:L19) | H19: ='1월'!H19+'2월'!H19 | I19: ='1월'!I19+'2월'!I19 | J19: ='1월'!J19+'2월'!J19 | K19: ='1월'!K19+'2월'!K19 | L19: ='1월'!L19+'2월'!L19 | M19: ='1월'!M19+'2월'!M19 | N19: =SUM(O19:U19) | O19: ='1월'!O19+'2월'!O19 | P19: ='1월'!P19+'2월'!P19 | Q19: ='1월'!Q19+'2월'!Q19 | R19: ='1월'!R19+'2월'!R19 | S19: ='1월'!S19+'2월'!S19 | T19: ='1월'!T19+'2월'!T19 | U19: ='1월'!U19+'2월'!U19
D20: =G20+M20+N20 | G20: =SUM(H20:L20) | H20: ='1월'!H20+'2월'!H20 | I20: ='1월'!I20+'2월'!I20 | J20: ='1월'!J20+'2월'!J20 | K20: ='1월'!K20+'2월'!K20 | L20: ='1월'!L20+'2월'!L20 | M20: ='1월'!M20+'2월'!M20 | N20: =SUM(O20:U20) | O20: ='1월'!O20+'2월'!O20 | P20: ='1월'!P20+'2월'!P20 | Q20: ='1월'!Q20+'2월'!Q20 | R20: ='1월'!R20+'2월'!R20 | S20: ='1월'!S20+'2월'!S20 | T20: ='1월'!T20+'2월'!T20 | U20: ='1월'!U20+'2월'!U20
D21: =G21+M21+N21 | G21: =SUM(H21:L21) | H21: ='1월'!H21+'2월'!H21 | I21: ='1월'!I21+'2월'!I21 | J21: ='1월'!J21+'2월'!J21 | K21: ='1월'!K21+'2월'!K21 | L21: ='1월'!L21+'2월'!L21 | M21: ='1월'!M21+'2월'!M21 | N21: =SUM(O21:U21) | O21: ='1월'!O21+'2월'!O21 | P21: ='1월'!P21+'2월'!P21 | Q21: ='1월'!Q21+'2월'!Q21 | R21: ='1월'!R21+'2월'!R21 | S21: ='1월'!S21+'2월'!S21 | T21: ='1월'!T21+'2월'!T21 | U21: ='1월'!U21+'2월'!U21
D22: =G22+M22+N22 | G22: =SUM(H22:L22) | H22: ='1월'!H22+'2월'!H22 | I22: ='1월'!I22+'2월'!I22 | J22: ='1월'!J22+'2월'!J22 | K22: ='1월'!K22+'2월'!K22 | L22: ='1월'!L22+'2월'!L22 | M22: ='1월'!M22+'2월'!M22 | N22: =SUM(O22:U22) | O22: ='1월'!O22+'2월'!O22 | P22: ='1월'!P22+'2월'!P22 | Q22: ='1월'!Q22+'2월'!Q22 | R22: ='1월'!R22+'2월'!R22 | S22: ='1월'!S22+'2월'!S22 | T22: ='1월'!T22+'2월'!T22 | U22: ='1월'!U22+'2월'!U22
D23: =G23+M23+N23 | G23: =SUM(H23:L23) | H23: ='1월'!H23+'2월'!H23 | I23: ='1월'!I23+'2월'!I23 | J23: ='1월'!J23+'2월'!J23 | K23: ='1월'!K23+'2월'!K23 | L23: ='1월'!L23+'2월'!L23 | M23: ='1월'!M23+'2월'!M23 | N23: =SUM(O23:U23) | O23: ='1월'!O23+'2월'!O23 | P23: ='1월'!P23+'2월'!P23 | Q23: ='1월'!Q23+'2월'!Q23 | R23: ='1월'!R23+'2월'!R23 | S23: ='1월'!S23+'2월'!S23 | T23: ='1월'!T23+'2월'!T23 | U23: ='1월'!U23+'2월'!U23
D24: =G24+M24+N24 | G24: =SUM(H24:L24) | H24: ='1월'!H24+'2월'!H24 | I24: ='1월'!I24+'2월'!I24 | J24: ='1월'!J24+'2월'!J24 | K24: ='1월'!K24+'2월'!K24 | L24: ='1월'!L24+'2월'!L24 | M24: ='1월'!M24+'2월'!M24 | N24: =SUM(O24:U24) | O24: ='1월'!O24+'2월'!O24 | P24: ='1월'!P24+'2월'!P24 | Q24: ='1월'!Q24+'2월'!Q24 | R24: ='1월'!R24+'2월'!R24 | S24: ='1월'!S24+'2월'!S24 | T24: ='1월'!T24+'2월'!T24 | U24: ='1월'!U24+'2월'!U24
D25: =G25+M25+N25 | G25: =SUM(H25:L25) | H25: ='1월'!H25+'2월'!H25 | I25: ='1월'!I25+'2월'!I25 | J25: ='1월'!J25+'2월'!J25 | K25: ='1월'!K25+'2월'!K25 | L25: ='1월'!L25+'2월'!L25 | M25: ='1월'!M25+'2월'!M25 | N25: =SUM(O25:U25) | O25: ='1월'!O25+'2월'!O25 | P25: ='1월'!P25+'2월'!P25 | Q25: ='1월'!Q25+'2월'!Q25 | R25: ='1월'!R25+'2월'!R25 | S25: ='1월'!S25+'2월'!S25 | T25: ='1월'!T25+'2월'!T25 | U25: ='1월'!U25+'2월'!U25
D26: =G26+M26+N26 | G26: =SUM(H26:L26) | H26: ='1월'!H26+'2월'!H26 | I26: ='1월'!I26+'2월'!I26 | J26: ='1월'!J26+'2월'!J26 | K26: ='1월'!K26+'2월'!K26 | L26: ='1월'!L26+'2월'!L26 | M26: ='1월'!M26+'2월'!M26 | N26: =SUM(O26:U26) | O26: ='1월'!O26+'2월'!O26 | P26: ='1월'!P26+'2월'!P26 | Q26: ='1월'!Q26+'2월'!Q26 | R26: ='1월'!R26+'2월'!R26 | S26: ='1월'!S26+'2월'!S26 | T26: ='1월'!T26+'2월'!T26 | U26: ='1월'!U26+'2월'!U26
D27: =G27+M27+N27 | G27: =SUM(H27:L27) | H27: ='1월'!H27+'2월'!H27 | I27: ='1월'!I27+'2월'!I27 | J27: ='1월'!J27+'2월'!J27 | K27: ='1월'!K27+'2월'!K27 | L27: ='1월'!L27+'2월'!L27 | M27: ='1월'!M27+'2월'!M27 | N27: =SUM(O27:U27) | O27: ='1월'!O27+'2월'!O27 | P27: ='1월'!P27+'2월'!P27 | Q27: ='1월'!Q27+'2월'!Q27 | R27: ='1월'!R27+'2월'!R27 | S27: ='1월'!S27+'2월'!S27 | T27: ='1월'!T27+'2월'!T27 | U27: ='1월'!U27+'2월'!U27
D28: =G28+M28+N28 | G28: =SUM(H28:L28) | H28: ='1월'!H28+'2월'!H28 | I28: ='1월'!I28+'2월'!I28 | J28: ='1월'!J28+'2월'!J28 | K28: ='1월'!K28+'2월'!K28 | L28: ='1월'!L28+'2월'!L28 | M28: ='1월'!M28+'2월'!M28 | N28: =SUM(O28:U28) | O28: ='1월'!O28+'2월'!O28 | P28: ='1월'!P28+'2월'!P28 | Q28: ='1월'!Q28+'2월'!Q28 | R28: ='1월'!R28+'2월'!R28 | S28: ='1월'!S28+'2월'!S28 | T28: ='1월'!T28+'2월'!T28 | U28: ='1월'!U28+'2월'!U28
D29: =G29+M29+N29 | G29: =SUM(H29:L29) | H29: =H6+H16 | I29: =I6+I16 | J29: =J6+J16 | K29: =K6+K16 | L29: =L6+L16 | M29: =M6+M16 | N29: =SUM(O29:U29) | O29: =O6+O16 | P29: =P6+P16 | Q29: =Q6+Q16 | R29: =R6+R16 | S29: =S6+S16 | T29: =T6+T16 | U29: =U6+U16
C36: =D6 | D36: =G36+M36+N36 | E36: =D36-C36 | F36: =IFERROR(D36/C36,0) | G36: =SUM(H36:L36) | H36: =SUM(H37:H41) | I36: =SUM(I37:I41) | J36: =SUM(J37:J41) | K36: =SUM(K37:K41) | L36: =SUM(L37:L41) | M36: =SUM(M37:M41) | N36: =SUM(O36:U36) | O36: =SUM(O37:O41) | P36: =SUM(P37:P41) | Q36: =SUM(Q37:Q41) | R36: =SUM(R37:R41) | S36: =SUM(S37:S41) | T36: =SUM(T37:T41) | U36: =SUM(U37:U41)
D37: =G37+M37+N37 | E37: =D37-C37 | F37: =IFERROR(D37/C37,"") | G37: =SUM(H37:L37) | N37: =SUM(O37:U37) | T37: ='1월'!T37+'2월'!T37 | U37: ='1월'!U37+'2월'!U37
D38: =G38+M38+N38 | E38: =D38-C38 | F38: =IFERROR(D38/C38,"") | G38: =SUM(H38:L38) | N38: =SUM(O38:U38) | T38: ='1월'!T38+'2월'!T38 | U38: ='1월'!U38+'2월'!U38
D39: =G39+M39+N39 | E39: =D39-C39 | F39: =IFERROR(D39/C39,"") | G39: =SUM(H39:L39) | N39: =SUM(O39:U39) | T39: ='1월'!T39+'2월'!T39 | U39: ='1월'!U39+'2월'!U39
D40: =G40+M40+N40 | E40: =D40-C40 | F40: =IFERROR(D40/C40,"") | G40: =SUM(H40:L40) | N40: =SUM(O40:U40) | T40: ='1월'!T40+'2월'!T40 | U40: ='1월'!U40+'2월'!U40
D41: =G41+M41+N41 | E41: =D41-C41 | F41: =IFERROR(D41/C41,"") | G41: =SUM(H41:L41) | N41: =SUM(O41:U41) | T41: =SUM(T42:T45) | U41: =SUM(U42:U45)
C42: =D12 | D42: =G42+M42+N42 | E42: =D42-C42 | F42: =IFERROR(D42/C42,0) | G42: =SUM(H42:L42) | N42: =SUM(O42:U42) | T42: ='1월'!T42+'2월'!T42 | U42: ='1월'!U42+'2월'!U42
C43: =D13 | D43: =G43+M43+N43 | E43: =D43-C43 | F43: =IFERROR(D43/C43,0) | G43: =SUM(H43:L43) | N43: =SUM(O43:U43) | T43: ='1월'!T43+'2월'!T43 | U43: ='1월'!U43+'2월'!U43
C44: =D14 | D44: =G44+M44+N44 | E44: =D44-C44 | F44: =IFERROR(D44/C44,0) | G44: =SUM(H44:L44) | N44: =SUM(O44:U44) | T44: ='1월'!T44+'2월'!T44 | U44: ='1월'!U44+'2월'!U44
C45: =D15 | D45: =G45+M45+N45 | E45: =D45-C45 | F45: =IFERROR(D45/C45,0) | G45: =SUM(H45:L45) | N45: =SUM(O45:U45) | T45: ='1월'!T45+'2월'!T45 | U45: ='1월'!U45+'2월'!U45
C46: =D16 | D46: =G46+M46+N46 | E46: =D46-C46 | F46: =IFERROR(D46/C46,0) | G46: =SUM(H46:L46) | H46: =SUM(H47:H58) | I46: =SUM(I47:I58) | J46: =SUM(J47:J58) | K46: =SUM(K47:K58) | L46: =SUM(L47:L58) | M46: =SUM(M47:M58) | N46: =SUM(O46:U46) | O46: =SUM(O47:O58) | P46: =SUM(P47:P58) | Q46: =SUM(Q47:Q58) | R46: =SUM(R47:R58) | S46: =SUM(S47:S58) | T46: =SUM(T47:T58) | U46: =SUM(U47:U58)
D47: =G47+M47+N47 | E47: =D47-C47 | F47: =IFERROR(D47/C47,"") | G47: =SUM(H47:L47) | N47: =SUM(O47:U47) | T47: ='1월'!T47+'2월'!T47 | U47: ='1월'!U47+'2월'!U47
D48: =G48+M48+N48 | E48: =D48-C48 | F48: =IFERROR(D48/C48,"") | G48: =SUM(H48:L48) | N48: =SUM(O48:U48) | T48: ='1월'!T48+'2월'!T48 | U48: ='1월'!U48+'2월'!U48
D49: =G49+M49+N49 | E49: =D49-C49 | F49: =IFERROR(D49/C49,"") | G49: =SUM(H49:L49) | N49: =SUM(O49:U49) | T49: ='1월'!T49+'2월'!T49 | U49: ='1월'!U49+'2월'!U49
D50: =G50+M50+N50 | E50: =D50-C50 | F50: =IFERROR(D50/C50,"") | G50: =SUM(H50:L50) | N50: =SUM(O50:U50) | T50: ='1월'!T50+'2월'!T50 | U50: ='1월'!U50+'2월'!U50
D51: =G51+M51+N51 | E51: =D51-C51 | F51: =IFERROR(D51/C51,"") | G51: =SUM(H51:L51) | N51: =SUM(O51:U51) | T51: ='1월'!T51+'2월'!T51 | U51: ='1월'!U51+'2월'!U51
...

Sheet 2월 누계_Diff
E5: =D5-C5 | F5: =IFERROR(D5/C5,"") | J5: =I5-H5 | K5: =IFERROR(I5/H5,"") | O5: =N5-M5 | P5: =IFERROR(N5/M5,"") | T5: =S5-R5 | U5: =IFERROR(S5/R5,"") | Y5: =X5-W5 | Z5: =IFERROR(X5/W5,"") | AD5: =AC5-AB5 | AE5: =IFERROR(AC5/AB5,"") | AI5: =AH5-AG5 | AJ5: =IFERROR(AH5/AG5,"")
E6: =D6-C6 | F6: =IFERROR(D6/C6,"") | J6: =I6-H6 | K6: =IFERROR(I6/H6,"") | O6: =N6-M6 | P6: =IFERROR(N6/M6,"") | T6: =S6-R6 | U6: =IFERROR(S6/R6,"") | Y6: =X6-W6 | Z6: =IFERROR(X6/W6,"") | AD6: =AC6-AB6 | AE6: =IFERROR(AC6/AB6,"") | AI6: =AH6-AG6 | AJ6: =IFERROR(AH6/AG6,"")
E7: =D7-C7 | F7: =IFERROR(D7/C7,"") | J7: =I7-H7 | K7: =IFERROR(I7/H7,"") | O7: =N7-M7 | P7: =IFERROR(N7/M7,"") | T7: =S7-R7 | U7: =IFERROR(S7/R7,"") | Y7: =X7-W7 | Z7: =IFERROR(X7/W7,"") | AD7: =AC7-AB7 | AE7: =IFERROR(AC7/AB7,"") | AI7: =AH7-AG7 | AJ7: =IFERROR(AH7/AG7,"")
E8: =D8-C8 | F8: =IFERROR(D8/C8,"") | J8: =I8-H8 | K8: =IFERROR(I8/H8,"") | O8: =N8-M8 | P8: =IFERROR(N8/M8,"") | T8: =S8-R8 | U8: =IFERROR(S8/R8,"") | Y8: =X8-W8 | Z8: =IFERROR(X8/W8,"") | AD8: =AC8-AB8 | AE8: =IFERROR(AC8/AB8,"") | AI8: =AH8-AG8 | AJ8: =IFERROR(AH8/AG8,"")
E9: =D9-C9 | F9: =IFERROR(D9/C9,"") | J9: =I9-H9 | K9: =IFERROR(I9/H9,"") | O9: =N9-M9 | P9: =IFERROR(N9/M9,"") | T9: =S9-R9 | U9: =IFERROR(S9/R9,"") | Y9: =X9-W9 | Z9: =IFERROR(X9/W9,"") | AD9: =AC9-AB9 | AE9: =IFERROR(AC9/AB9,"") | AI9: =AH9-AG9 | AJ9: =IFERROR(AH9/AG9,"")
E10: =D10-C10 | F10: =IFERROR(D10/C10,"") | J10: =I10-H10 | K10: =IFERROR(I10/H10,"") | O10: =N10-M10 | P10: =IFERROR(N10/M10,"") | T10: =S10-R10 | U10: =IFERROR(S10/R10,"") | Y10: =X10-W10 | Z10: =IFERROR(X10/W10,"") | AD10: =AC10-AB10 | AE10: =IFERROR(AC10/AB10,"") | AI10: =AH10-AG10 | AJ10: =IFERROR(AH10/AG10,"")
C11: =SUM(C5:C10) | D11: =SUM(D5:D10) | E11: =D11-C11 | F11: =IFERROR(D11/C11,"") | H11: =SUM(H5:H10) | I11: =SUM(I5:I10) | J11: =I11-H11 | K11: =IFERROR(I11/H11,"") | M11: =SUM(M5:M10) | N11: =SUM(N5:N10) | O11: =N11-M11 | P11: =IFERROR(N11/M11,"") | R11: =SUM(R5:R10) | S11: =SUM(S5:S10) | T11: =S11-R11 | U11: =IFERROR(S11/R11,"") | W11: =SUM(W5:W10) | X11: =SUM(X5:X10) | Y11: =X11-W11 | Z11: =IFERROR(X11/W11,"") | AB11: =SUM(AB5:AB10) | AC11: =SUM(AC5:AC10) | AD11: =AC11-AB11 | AE11: =IFERROR(AC11/AB11,"") | AG11: =SUM(AG5:AG10) | AH11: =SUM(AH5:AH10) | AI11: =AH11-AG11 | AJ11: =IFERROR(AH11/AG11,"")
E12: =D12-C12 | F12: =IFERROR(D12/C12,"") | J12: =I12-H12 | K12: =IFERROR(I12/H12,"") | O12: =N12-M12 | P12: =IFERROR(N12/M12,"") | T12: =S12-R12 | U12: =IFERROR(S12/R12,"") | Y12: =X12-W12 | Z12: =IFERROR(X12/W12,"") | AD12: =AC12-AB12 | AE12: =IFERROR(AC12/AB12,"") | AI12: =AH12-AG12 | AJ12: =IFERROR(AH12/AG12,"")
E13: =D13-C13 | F13: =IFERROR(D13/C13,"") | J13: =I13-H13 | K13: =IFERROR(I13/H13,"") | O13: =N13-M13 | P13: =IFERROR(N13/M13,"") | T13: =S13-R13 | U13: =IFERROR(S13/R13,"") | Y13: =X13-W13 | Z13: =IFERROR(X13/W13,"") | AD13: =AC13-AB13 | AE13: =IFERROR(AC13/AB13,"") | AI13: =AH13-AG13 | AJ13: =IFERROR(AH13/AG13,"")
E14: =D14-C14 | F14: =IFERROR(D14/C14,"") | J14: =I14-H14 | K14: =IFERROR(I14/H14,"") | O14: =N14-M14 | P14: =IFERROR(N14/M14,"") | T14: =S14-R14 | U14: =IFERROR(S14/R14,"") | Y14: =X14-W14 | Z14: =IFERROR(X14/W14,"") | AD14: =AC14-AB14 | AE14: =IFERROR(AC14/AB14,"") | AI14: =AH14-AG14 | AJ14: =IFERROR(AH14/AG14,"")
E15: =D15-C15 | F15: =IFERROR(D15/C15,"") | J15: =I15-H15 | K15: =IFERROR(I15/H15,"") | O15: =N15-M15 | P15: =IFERROR(N15/M15,"") | T15: =S15-R15 | U15: =IFERROR(S15/R15,"") | Y15: =X15-W15 | Z15: =IFERROR(X15/W15,"") | AD15: =AC15-AB15 | AE15: =IFERROR(AC15/AB15,"") | AI15: =AH15-AG15 | AJ15: =IFERROR(AH15/AG15,"")
E16: =D16-C16 | F16: =IFERROR(D16/C16,"") | J16: =I16-H16 | K16: =IFERROR(I16/H16,"") | O16: =N16-M16 | P16: =IFERROR(N16/M16,"") | T16: =S16-R16 | U16: =IFERROR(S16/R16,"") | Y16: =X16-W16 | Z16: =IFERROR(X16/W16,"") | AD16: =AC16-AB16 | AE16: =IFERROR(AC16/AB16,"") | AI16: =AH16-AG16 | AJ16: =IFERROR(AH16/AG16,"")
E17: =D17-C17 | F17: =IFERROR(D17/C17,"") | J17: =I17-H17 | K17: =IFERROR(I17/H17,"") | O17: =N17-M17 | P17: =IFERROR(N17/M17,"") | T17: =S17-R17 | U17: =IFERROR(S17/R17,"") | Y17: =X17-W17 | Z17: =IFERROR(X17/W17,"") | AD17: =AC17-AB17 | AE17: =IFERROR(AC17/AB17,"") | AI17: =AH17-AG17 | AJ17: =IFERROR(AH17/AG17,"")
C18: =SUM(C12:C17) | D18: =SUM(D12:D17) | E18: =D18-C18 | F18: =IFERROR(D18/C18,"") | H18: =SUM(H12:H17) | I18: =SUM(I12:I17) | J18: =I18-H18 | K18: =IFERROR(I18/H18,"") | M18: =SUM(M12:M17) | N18: =SUM(N12:N17) | O18: =N18-M18 | P18: =IFERROR(N18/M18,"") | R18: =SUM(R12:R17) | S18: =SUM(S12:S17) | T18: =S18-R18 | U18: =IFERROR(S18/R18,"") | W18: =SUM(W12:W17) | X18: =SUM(X12:X17) | Y18: =X18-W18 | Z18: =IFERROR(X18/W18,"") | AB18: =SUM(AB12:AB17) | AC18: =SUM(AC12:AC17) | AD18: =AC18-AB18 | AE18: =IFERROR(AC18/AB18,"") | AG18: =SUM(AG12:AG17) | AH18: =SUM(AH12:AH17) | AI18: =AH18-AG18 | AJ18: =IFERROR(AH18/AG18,"")
C19: =C11+C18 | D19: =D11+D18 | E19: =D19-C19 | F19: =IFERROR(D19/C19,"") | H19: =H11+H18 | I19: =I11+I18 | J19: =I19-H19 | K19: =IFERROR(I19/H19,"") | M19: =M11+M18 | N19: =N11+N18 | O19: =N19-M19 | P19: =IFERROR(N19/M19,"") | R19: =R11+R18 | S19: =S11+S18 | T19: =S19-R19 | U19: =IFERROR(S19/R19,"") | W19: =W11+W18 | X19: =X11+X18 | Y19: =X19-W19 | Z19: =IFERROR(X19/W19,"") | AB19: =AB11+AB18 | AC19: =AC11+AC18 | AD19: =AC19-AB19 | AE19: =IFERROR(AC19/AB19,"") | AG19: =AG11+AG18 | AH19: =AH11+AH18 | AI19: =AH19-AG19 | AJ19: =IFERROR(AH19/AG19,"")

Sheet 3월
D6: =G6+M6+N6 | G6: =SUM(H6:L6) | H6: =SUM(H7:H11) | I6: =SUM(I7:I11) | J6: =SUM(J7:J11) | K6: =SUM(K7:K11) | L6: =SUM(L7:L11) | M6: =SUM(M7:M11) | N6: =SUM(O6:U6) | O6: =SUM(O7:O11) | P6: =SUM(P7:P11) | Q6: =SUM(Q7:Q11) | R6: =SUM(R7:R11) | S6: =SUM(S7:S11) | T6: =SUM(T7:T11) | U6: =SUM(U7:U11)
D7: =G7+M7+N7 | G7: =SUM(H7:L7) | N7: =SUM(O7:U7)
D8: =G8+M8+N8 | G8: =SUM(H8:L8) | N8: =SUM(O8:U8)
D9: =G9+M9+N9 | G9: =SUM(H9:L9) | N9: =SUM(O9:U9)
D10: =G10+M10+N10 | G10: =SUM(H10:L10) | N10: =SUM(O10:U10)
D11: =G11+M11+N11 | G11: =SUM(H11:L11) | H11: =SUM(H12:H15) | I11: =SUM(I12:I15) | J11: =SUM(J12:J15) | K11: =SUM(K12:K15) | L11: =SUM(L12:L15) | M11: =SUM(M12:M15) | N11: =SUM(O11:U11) | O11: =SUM(O12:O15) | P11: =SUM(P12:P15) | Q11: =SUM(Q12:Q15) | R11: =SUM(R12:R15) | S11: =SUM(S12:S15) | T11: =SUM(T12:T15) | U11: =SUM(U12:U15)
D12: =G12+M12+N12 | G12: =SUM(H12:L12) | N12: =SUM(O12:U12)
D13: =G13+M13+N13 | G13: =SUM(H13:L13) | N13: =SUM(O13:U13)
D14: =G14+M14+N14 | G14: =SUM(H14:L14) | N14: =SUM(O14:U14)
D15: =G15+M15+N15 | G15: =SUM(H15:L15) | N15: =SUM(O15:U15)
D16: =G16+M16+N16 | G16: =SUM(H16:L16) | H16: =SUM(H17:H28) | I16: =SUM(I17:I28) | J16: =SUM(J17:J28) | K16: =SUM(K17:K28) | L16: =SUM(L17:L28) | M16: =SUM(M17:M28) | N16: =SUM(O16:U16) | O16: =SUM(O17:O28) | P16: =SUM(P17:P28) | Q16: =SUM(Q17:Q28) | R16: =SUM(R17:R28) | S16: =SUM(S17:S28) | T16: =SUM(T17:T28) | U16: =SUM(U17:U28)
D17: =G17+M17+N17 | G17: =SUM(H17:L17) | N17: =SUM(O17:U17)
D18: =G18+M18+N18 | G18: =SUM(H18:L18) | N18: =SUM(O18:U18)
D19: =G19+M19+N19 | G19: =SUM(H19:L19) | N19: =SUM(O19:U19)
D20: =G20+M20+N20 | G20: =SUM(H20:L20) | N20: =SUM(O20:U20)
D21: =G21+M21+N21 | G21: =SUM(H21:L21) | N21: =SUM(O21:U21)
D22: =G22+M22+N22 | G22: =SUM(H22:L22) | N22: =SUM(O22:U22)
D23: =G23+M23+N23 | G23: =SUM(H23:L23) | N23: =SUM(O23:U23)
D24: =G24+M24+N24 | G24: =SUM(H24:L24) | N24: =SUM(O24:U24)
D25: =G25+M25+N25 | G25: =SUM(H25:L25) | N25: =SUM(O25:U25)
D26: =G26+M26+N26 | G26: =SUM(H26:L26) | N26: =SUM(O26:U26)
D27: =G27+M27+N27 | G27: =SUM(H27:L27) | N27: =SUM(O27:U27)
D28: =G28+M28+N28 | G28: =SUM(H28:L28) | N28: =SUM(O28:U28)
D29: =G29+M29+N29 | G29: =SUM(H29:L29) | H29: =H6+H16 | I29: =I6+I16 | J29: =J6+J16 | K29: =K6+K16 | L29: =L6+L16 | M29: =M6+M16 | N29: =SUM(O29:U29) | O29: =O6+O16 | P29: =P6+P16 | Q29: =Q6+Q16 | R29: =R6+R16 | S29: =S6+S16 | T29: =T6+T16 | U29: =U6+U16
C36: =D6 | D36: =G36+M36+N36 | E36: =D36-C36 | F36: =IFERROR(D36/C36,0) | G36: =SUM(H36:L36) | H36: =SUM(H37:H41) | I36: =SUM(I37:I41) | J36: =SUM(J37:J41) | K36: =SUM(K37:K41) | L36: =SUM(L37:L41) | M36: =SUM(M37:M41) | N36: =SUM(O36:U36) | O36: =SUM(O37:O41) | P36: =SUM(P37:P41) | Q36: =SUM(Q37:Q41) | R36: =SUM(R37:R41) | S36: =SUM(S37:S41) | T36: =SUM(T37:T41) | U36: =SUM(U37:U41)
D37: =G37+M37+N37 | E37: =D37-C37 | F37: =IFERROR(D37/C37,"") | G37: =SUM(H37:L37) | N37: =SUM(O37:U37)
D38: =G38+M38+N38 | E38: =D38-C38 | F38: =IFERROR(D38/C38,"") | G38: =SUM(H38:L38) | N38: =SUM(O38:U38)
D39: =G39+M39+N39 | E39: =D39-C39 | F39: =IFERROR(D39/C39,"") | G39: =SUM(H39:L39) | N39: =SUM(O39:U39)
D40: =G40+M40+N40 | E40: =D40-C40 | F40: =IFERROR(D40/C40,"") | G40: =SUM(H40:L40) | N40: =SUM(O40:U40)
D41: =G41+M41+N41 | E41: =D41-C41 | F41: =IFERROR(D41/C41,"") | G41: =SUM(H41:L41) | N41: =SUM(O41:U41) | T41: =SUM(T42:T45) | U41: =SUM(U42:U45)
C42: =D12 | D42: =G42+M42+N42 | E42: =D42-C42 | F42: =IFERROR(D42/C42,0) | G42: =SUM(H42:L42) | N42: =SUM(O42:U42)
C43: =D13 | D43: =G43+M43+N43 | E43: =D43-C43 | F43: =IFERROR(D43/C43,0) | G43: =SUM(H43:L43) | N43: =SUM(O43:U43)
C44: =D14 | D44: =G44+M44+N44 | E44: =D44-C44 | F44: =IFERROR(D44/C44,0) | G44: =SUM(H44:L44) | N44: =SUM(O44:U44)
C45: =D15 | D45: =G45+M45+N45 | E45: =D45-C45 | F45: =IFERROR(D45/C45,0) | G45: =SUM(H45:L45) | N45: =SUM(O45:U45)
C46: =D16 | D46: =G46+M46+N46 | E46: =D46-C46 | F46: =IFERROR(D46/C46,0) | G46: =SUM(H46:L46) | H46: =SUM(H47:H58) | I46: =SUM(I47:I58) | J46: =SUM(J47:J58) | K46: =SUM(K47:K58) | L46: =SUM(L47:L58) | M46: =SUM(M47:M58) | N46: =SUM(O46:U46) | O46: =SUM(O47:O58) | P46: =SUM(P47:P58) | Q46: =SUM(Q47:Q58) | R46: =SUM(R47:R58) | S46: =SUM(S47:S58) | T46: =SUM(T47:T58) | U46: =SUM(U47:U58)
D47: =G47+M47+N47 | E47: =D47-C47 | F47: =IFERROR(D47/C47,"") | G47: =SUM(H47:L47) | N47: =SUM(O47:U47)
D48: =G48+M48+N48 | E48: =D48-C48 | F48: =IFERROR(D48/C48,"") | G48: =SUM(H48:L48) | N48: =SUM(O48:U48)
D49: =G49+M49+N49 | E49: =D49-C49 | F49: =IFERROR(D49/C49,"") | G49: =SUM(H49:L49) | N49: =SUM(O49:U49)
D50: =G50+M50+N50 | E50: =D50-C50 | F50: =IFERROR(D50/C50,"") | G50: =SUM(H50:L50) | N50: =SUM(O50:U50)
D51: =G51+M51+N51 | E51: =D51-C51 | F51: =IFERROR(D51/C51,"") | G51: =SUM(H51:L51) | N51: =SUM(O51:U51)
...

Sheet 3월 누계
D6: =G6+M6+N6 | G6: =SUM(H6:L6) | H6: =SUM(H7:H11) | I6: =SUM(I7:I11) | J6: =SUM(J7:J11) | K6: =SUM(K7:K11) | L6: =SUM(L7:L11) | M6: =SUM(M7:M11) | N6: =SUM(O6:U6) | O6: =SUM(O7:O11) | P6: =SUM(P7:P11) | Q6: =SUM(Q7:Q11) | R6: =SUM(R7:R11) | S6: =SUM(S7:S11) | T6: =SUM(T7:T11) | U6: =SUM(U7:U11)
D7: =G7+M7+N7 | G7: =SUM(H7:L7) | H7: ='2월 누계'!H7+'3월'!H7 | I7: ='2월 누계'!I7+'3월'!I7 | J7: ='2월 누계'!J7+'3월'!J7 | K7: ='2월 누계'!K7+'3월'!K7 | L7: ='2월 누계'!L7+'3월'!L7 | M7: ='2월 누계'!M7+'3월'!M7 | N7: =SUM(O7:U7) | O7: ='2월 누계'!O7+'3월'!O7 | P7: ='2월 누계'!P7+'3월'!P7 | Q7: ='2월 누계'!Q7+'3월'!Q7 | R7: ='2월 누계'!R7+'3월'!R7 | S7: ='2월 누계'!S7+'3월'!S7 | T7: ='2월 누계'!T7+'3월'!T7 | U7: ='2월 누계'!U7+'3월'!U7
D8: =G8+M8+N8 | G8: =SUM(H8:L8) | H8: ='2월 누계'!H8+'3월'!H8 | I8: ='2월 누계'!I8+'3월'!I8 | J8: ='2월 누계'!J8+'3월'!J8 | K8: ='2월 누계'!K8+'3월'!K8 | L8: ='2월 누계'!L8+'3월'!L8 | M8: ='2월 누계'!M8+'3월'!M8 | N8: =SUM(O8:U8) | O8: ='2월 누계'!O8+'3월'!O8 | P8: ='2월 누계'!P8+'3월'!P8 | Q8: ='2월 누계'!Q8+'3월'!Q8 | R8: ='2월 누계'!R8+'3월'!R8 | S8: ='2월 누계'!S8+'3월'!S8 | T8: ='2월 누계'!T8+'3월'!T8 | U8: ='2월 누계'!U8+'3월'!U8
D9: =G9+M9+N9 | G9: =SUM(H9:L9) | H9: ='2월 누계'!H9+'3월'!H9 | I9: ='2월 누계'!I9+'3월'!I9 | J9: ='2월 누계'!J9+'3월'!J9 | K9: ='2월 누계'!K9+'3월'!K9 | L9: ='2월 누계'!L9+'3월'!L9 | M9: ='2월 누계'!M9+'3월'!M9 | N9: =SUM(O9:U9) | O9: ='2월 누계'!O9+'3월'!O9 | P9: ='2월 누계'!P9+'3월'!P9 | Q9: ='2월 누계'!Q9+'3월'!Q9 | R9: ='2월 누계'!R9+'3월'!R9 | S9: ='2월 누계'!S9+'3월'!S9 | T9: ='2월 누계'!T9+'3월'!T9 | U9: ='2월 누계'!U9+'3월'!U9
D10: =G10+M10+N10 | G10: =SUM(H10:L10) | H10: ='2월 누계'!H10+'3월'!H10 | I10: ='2월 누계'!I10+'3월'!I10 | J10: ='2월 누계'!J10+'3월'!J10 | K10: ='2월 누계'!K10+'3월'!K10 | L10: ='2월 누계'!L10+'3월'!L10 | M10: ='2월 누계'!M10+'3월'!M10 | N10: =SUM(O10:U10) | O10: ='2월 누계'!O10+'3월'!O10 | P10: ='2월 누계'!P10+'3월'!P10 | Q10: ='2월 누계'!Q10+'3월'!Q10 | R10: ='2월 누계'!R10+'3월'!R10 | S10: ='2월 누계'!S10+'3월'!S10 | T10: ='2월 누계'!T10+'3월'!T10 | U10: ='2월 누계'!U10+'3월'!U10
D11: =G11+M11+N11 | G11: =SUM(H11:L11) | H11: =SUM(H12:H15) | I11: =SUM(I12:I15) | J11: =SUM(J12:J15) | K11: =SUM(K12:K15) | L11: =SUM(L12:L15) | M11: =SUM(M12:M15) | N11: =SUM(O11:U11) | O11: =SUM(O12:O15) | P11: =SUM(P12:P15) | Q11: =SUM(Q12:Q15) | R11: =SUM(R12:R15) | S11: =SUM(S12:S15) | T11: =SUM(T12:T15) | U11: =SUM(U12:U15)
D12: =G12+M12+N12 | G12: =SUM(H12:L12) | H12: ='2월 누계'!H12+'3월'!H12 | I12: ='2월 누계'!I12+'3월'!I12 | J12: ='2월 누계'!J12+'3월'!J12 | K12: ='2월 누계'!K12+'3월'!K12 | L12: ='2월 누계'!L12+'3월'!L12 | M12: ='2월 누계'!M12+'3월'!M12 | N12: =SUM(O12:U12) | O12: ='2월 누계'!O12+'3월'!O12 | P12: ='2월 누계'!P12+'3월'!P12 | Q12: ='2월 누계'!Q12+'3월'!Q12 | R12: ='2월 누계'!R12+'3월'!R12 | S12: ='2월 누계'!S12+'3월'!S12 | T12: ='2월 누계'!T12+'3월'!T12 | U12: ='2월 누계'!U12+'3월'!U12
D13: =G13+M13+N13 | G13: =SUM(H13:L13) | H13: ='2월 누계'!H13+'3월'!H13 | I13: ='2월 누계'!I13+'3월'!I13 | J13: ='2월 누계'!J13+'3월'!J13 | K13: ='2월 누계'!K13+'3월'!K13 | L13: ='2월 누계'!L13+'3월'!L13 | M13: ='2월 누계'!M13+'3월'!M13 | N13: =SUM(O13:U13) | O13: ='2월 누계'!O13+'3월'!O13 | P13: ='2월 누계'!P13+'3월'!P13 | Q13: ='2월 누계'!Q13+'3월'!Q13 | R13: ='2월 누계'!R13+'3월'!R13 | S13: ='2월 누계'!S13+'3월'!S13 | T13: ='2월 누계'!T13+'3월'!T13 | U13: ='2월 누계'!U13+'3월'!U13
D14: =G14+M14+N14 | G14: =SUM(H14:L14) | H14: ='2월 누계'!H14+'3월'!H14 | I14: ='2월 누계'!I14+'3월'!I14 | J14: ='2월 누계'!J14+'3월'!J14 | K14: ='2월 누계'!K14+'3월'!K14 | L14: ='2월 누계'!L14+'3월'!L14 | M14: ='2월 누계'!M14+'3월'!M14 | N14: =SUM(O14:U14) | O14: ='2월 누계'!O14+'3월'!O14 | P14: ='2월 누계'!P14+'3월'!P14 | Q14: ='2월 누계'!Q14+'3월'!Q14 | R14: ='2월 누계'!R14+'3월'!R14 | S14: ='2월 누계'!S14+'3월'!S14 | T14: ='2월 누계'!T14+'3월'!T14 | U14: ='2월 누계'!U14+'3월'!U14
D15: =G15+M15+N15 | G15: =SUM(H15:L15) | H15: ='2월 누계'!H15+'3월'!H15 | I15: ='2월 누계'!I15+'3월'!I15 | J15: ='2월 누계'!J15+'3월'!J15 | K15: ='2월 누계'!K15+'3월'!K15 | L15: ='2월 누계'!L15+'3월'!L15 | M15: ='2월 누계'!M15+'3월'!M15 | N15: =SUM(O15:U15) | O15: ='2월 누계'!O15+'3월'!O15 | P15: ='2월 누계'!P15+'3월'!P15 | Q15: ='2월 누계'!Q15+'3월'!Q15 | R15: ='2월 누계'!R15+'3월'!R15 | S15: ='2월 누계'!S15+'3월'!S15 | T15: ='2월 누계'!T15+'3월'!T15 | U15: ='2월 누계'!U15+'3월'!U15
D16: =G16+M16+N16 | G16: =SUM(H16:L16) | H16: =SUM(H17:H28) | I16: =SUM(I17:I28) | J16: =SUM(J17:J28) | K16: =SUM(K17:K28) | L16: =SUM(L17:L28) | M16: =SUM(M17:M28) | N16: =SUM(O16:U16) | O16: =SUM(O17:O28) | P16: =SUM(P17:P28) | Q16: =SUM(Q17:Q28) | R16: =SUM(R17:R28) | S16: =SUM(S17:S28) | T16: =SUM(T17:T28) | U16: =SUM(U17:U28)
D17: =G17+M17+N17 | G17: =SUM(H17:L17) | H17: ='2월 누계'!H17+'3월'!H17 | I17: ='2월 누계'!I17+'3월'!I17 | J17: ='2월 누계'!J17+'3월'!J17 | K17: ='2월 누계'!K17+'3월'!K17 | L17: ='2월 누계'!L17+'3월'!L17 | M17: ='2월 누계'!M17+'3월'!M17 | N17: =SUM(O17:U17) | O17: ='2월 누계'!O17+'3월'!O17 | P17: ='2월 누계'!P17+'3월'!P17 | Q17: ='2월 누계'!Q17+'3월'!Q17 | R17: ='2월 누계'!R17+'3월'!R17 | S17: ='2월 누계'!S17+'3월'!S17 | T17: ='2월 누계'!T17+'3월'!T17 | U17: ='2월 누계'!U17+'3월'!U17
D18: =G18+M18+N18 | G18: =SUM(H18:L18) | H18: ='2월 누계'!H18+'3월'!H18 | I18: ='2월 누계'!I18+'3월'!I18 | J18: ='2월 누계'!J18+'3월'!J18 | K18: ='2월 누계'!K18+'3월'!K18 | L18: ='2월 누계'!L18+'3월'!L18 | M18: ='2월 누계'!M18+'3월'!M18 | N18: =SUM(O18:U18) | O18: ='2월 누계'!O18+'3월'!O18 | P18: ='2월 누계'!P18+'3월'!P18 | Q18: ='2월 누계'!Q18+'3월'!Q18 | R18: ='2월 누계'!R18+'3월'!R18 | S18: ='2월 누계'!S18+'3월'!S18 | T18: ='2월 누계'!T18+'3월'!T18 | U18: ='2월 누계'!U18+'3월'!U18
D19: =G19+M19+N19 | G19: =SUM(H19:L19) | H19: ='2월 누계'!H19+'3월'!H19 | I19: ='2월 누계'!I19+'3월'!I19 | J19: ='2월 누계'!J19+'3월'!J19 | K19: ='2월 누계'!K19+'3월'!K19 | L19: ='2월 누계'!L19+'3월'!L19 | M19: ='2월 누계'!M19+'3월'!M19 | N19: =SUM(O19:U19) | O19: ='2월 누계'!O19+'3월'!O19 | P19: ='2월 누계'!P19+'3월'!P19 | Q19: ='2월 누계'!Q19+'3월'!Q19 | R19: ='2월 누계'!R19+'3월'!R19 | S19: ='2월 누계'!S19+'3월'!S19 | T19: ='2월 누계'!T19+'3월'!T19 | U19: ='2월 누계'!U19+'3월'!U19
D20: =G20+M20+N20 | G20: =SUM(H20:L20) | H20: ='2월 누계'!H20+'3월'!H20 | I20: ='2월 누계'!I20+'3월'!I20 | J20: ='2월 누계'!J20+'3월'!J20 | K20: ='2월 누계'!K20+'3월'!K20 | L20: ='2월 누계'!L20+'3월'!L20 | M20: ='2월 누계'!M20+'3월'!M20 | N20: =SUM(O20:U20) | O20: ='2월 누계'!O20+'3월'!O20 | P20: ='2월 누계'!P20+'3월'!P20 | Q20: ='2월 누계'!Q20+'3월'!Q20 | R20: ='2월 누계'!R20+'3월'!R20 | S20: ='2월 누계'!S20+'3월'!S20 | T20: ='2월 누계'!T20+'3월'!T20 | U20: ='2월 누계'!U20+'3월'!U20
D21: =G21+M21+N21 | G21: =SUM(H21:L21) | H21: ='2월 누계'!H21+'3월'!H21 | I21: ='2월 누계'!I21+'3월'!I21 | J21: ='2월 누계'!J21+'3월'!J21 | K21: ='2월 누계'!K21+'3월'!K21 | L21: ='2월 누계'!L21+'3월'!L21 | M21: ='2월 누계'!M21+'3월'!M21 | N21: =SUM(O21:U21) | O21: ='2월 누계'!O21+'3월'!O21 | P21: ='2월 누계'!P21+'3월'!P21 | Q21: ='2월 누계'!Q21+'3월'!Q21 | R21: ='2월 누계'!R21+'3월'!R21 | S21: ='2월 누계'!S21+'3월'!S21 | T21: ='2월 누계'!T21+'3월'!T21 | U21: ='2월 누계'!U21+'3월'!U21
D22: =G22+M22+N22 | G22: =SUM(H22:L22) | H22: ='2월 누계'!H22+'3월'!H22 | I22: ='2월 누계'!I22+'3월'!I22 | J22: ='2월 누계'!J22+'3월'!J22 | K22: ='2월 누계'!K22+'3월'!K22 | L22: ='2월 누계'!L22+'3월'!L22 | M22: ='2월 누계'!M22+'3월'!M22 | N22: =SUM(O22:U22) | O22: ='2월 누계'!O22+'3월'!O22 | P22: ='2월 누계'!P22+'3월'!P22 | Q22: ='2월 누계'!Q22+'3월'!Q22 | R22: ='2월 누계'!R22+'3월'!R22 | S22: ='2월 누계'!S22+'3월'!S22 | T22: ='2월 누계'!T22+'3월'!T22 | U22: ='2월 누계'!U22+'3월'!U22
D23: =G23+M23+N23 | G23: =SUM(H23:L23) | H23: ='2월 누계'!H23+'3월'!H23 | I23: ='2월 누계'!I23+'3월'!I23 | J23: ='2월 누계'!J23+'3월'!J23 | K23: ='2월 누계'!K23+'3월'!K23 | L23: ='2월 누계'!L23+'3월'!L23 | M23: ='2월 누계'!M23+'3월'!M23 | N23: =SUM(O23:U23) | O23: ='2월 누계'!O23+'3월'!O23 | P23: ='2월 누계'!P23+'3월'!P23 | Q23: ='2월 누계'!Q23+'3월'!Q23 | R23: ='2월 누계'!R23+'3월'!R23 | S23: ='2월 누계'!S23+'3월'!S23 | T23: ='2월 누계'!T23+'3월'!T23 | U23: ='2월 누계'!U23+'3월'!U23
D24: =G24+M24+N24 | G24: =SUM(H24:L24) | H24: ='2월 누계'!H24+'3월'!H24 | I24: ='2월 누계'!I24+'3월'!I24 | J24: ='2월 누계'!J24+'3월'!J24 | K24: ='2월 누계'!K24+'3월'!K24 | L24: ='2월 누계'!L24+'3월'!L24 | M24: ='2월 누계'!M24+'3월'!M24 | N24: =SUM(O24:U24) | O24: ='2월 누계'!O24+'3월'!O24 | P24: ='2월 누계'!P24+'3월'!P24 | Q24: ='2월 누계'!Q24+'3월'!Q24 | R24: ='2월 누계'!R24+'3월'!R24 | S24: ='2월 누계'!S24+'3월'!S24 | T24: ='2월 누계'!T24+'3월'!T24 | U24: ='2월 누계'!U24+'3월'!U24
D25: =G25+M25+N25 | G25: =SUM(H25:L25) | H25: ='2월 누계'!H25+'3월'!H25 | I25: ='2월 누계'!I25+'3월'!I25 | J25: ='2월 누계'!J25+'3월'!J25 | K25: ='2월 누계'!K25+'3월'!K25 | L25: ='2월 누계'!L25+'3월'!L25 | M25: ='2월 누계'!M25+'3월'!M25 | N25: =SUM(O25:U25) | O25: ='2월 누계'!O25+'3월'!O25 | P25: ='2월 누계'!P25+'3월'!P25 | Q25: ='2월 누계'!Q25+'3월'!Q25 | R25: ='2월 누계'!R25+'3월'!R25 | S25: ='2월 누계'!S25+'3월'!S25 | T25: ='2월 누계'!T25+'3월'!T25 | U25: ='2월 누계'!U25+'3월'!U25
D26: =G26+M26+N26 | G26: =SUM(H26:L26) | H26: ='2월 누계'!H26+'3월'!H26 | I26: ='2월 누계'!I26+'3월'!I26 | J26: ='2월 누계'!J26+'3월'!J26 | K26: ='2월 누계'!K26+'3월'!K26 | L26: ='2월 누계'!L26+'3월'!L26 | M26: ='2월 누계'!M26+'3월'!M26 | N26: =SUM(O26:U26) | O26: ='2월 누계'!O26+'3월'!O26 | P26: ='2월 누계'!P26+'3월'!P26 | Q26: ='2월 누계'!Q26+'3월'!Q26 | R26: ='2월 누계'!R26+'3월'!R26 | S26: ='2월 누계'!S26+'3월'!S26 | T26: ='2월 누계'!T26+'3월'!T26 | U26: ='2월 누계'!U26+'3월'!U26
D27: =G27+M27+N27 | G27: =SUM(H27:L27) | H27: ='2월 누계'!H27+'3월'!H27 | I27: ='2월 누계'!I27+'3월'!I27 | J27: ='2월 누계'!J27+'3월'!J27 | K27: ='2월 누계'!K27+'3월'!K27 | L27: ='2월 누계'!L27+'3월'!L27 | M27: ='2월 누계'!M27+'3월'!M27 | N27: =SUM(O27:U27) | O27: ='2월 누계'!O27+'3월'!O27 | P27: ='2월 누계'!P27+'3월'!P27 | Q27: ='2월 누계'!Q27+'3월'!Q27 | R27: ='2월 누계'!R27+'3월'!R27 | S27: ='2월 누계'!S27+'3월'!S27 | T27: ='2월 누계'!T27+'3월'!T27 | U27: ='2월 누계'!U27+'3월'!U27
D28: =G28+M28+N28 | G28: =SUM(H28:L28) | H28: ='2월 누계'!H28+'3월'!H28 | I28: ='2월 누계'!I28+'3월'!I28 | J28: ='2월 누계'!J28+'3월'!J28 | K28: ='2월 누계'!K28+'3월'!K28 | L28: ='2월 누계'!L28+'3월'!L28 | M28: ='2월 누계'!M28+'3월'!M28 | N28: =SUM(O28:U28) | O28: ='2월 누계'!O28+'3월'!O28 | P28: ='2월 누계'!P28+'3월'!P28 | Q28: ='2월 누계'!Q28+'3월'!Q28 | R28: ='2월 누계'!R28+'3월'!R28 | S28: ='2월 누계'!S28+'3월'!S28 | T28: ='2월 누계'!T28+'3월'!T28 | U28: ='2월 누계'!U28+'3월'!U28
D29: =G29+M29+N29 | G29: =SUM(H29:L29) | H29: =H6+H16 | I29: =I6+I16 | J29: =J6+J16 | K29: =K6+K16 | L29: =L6+L16 | M29: =M6+M16 | N29: =SUM(O29:U29) | O29: =O6+O16 | P29: =P6+P16 | Q29: =Q6+Q16 | R29: =R6+R16 | S29: =S6+S16 | T29: =T6+T16 | U29: =U6+U16
C36: =D6 | D36: =G36+M36+N36 | E36: =D36-C36 | F36: =IFERROR(D36/C36,0) | G36: =SUM(H36:L36) | H36: =SUM(H37:H41) | I36: =SUM(I37:I41) | J36: =SUM(J37:J41) | K36: =SUM(K37:K41) | L36: =SUM(L37:L41) | M36: =SUM(M37:M41) | N36: =SUM(O36:U36) | O36: =SUM(O37:O41) | P36: =SUM(P37:P41) | Q36: =SUM(Q37:Q41) | R36: =SUM(R37:R41) | S36: =SUM(S37:S41) | T36: =SUM(T37:T41) | U36: =SUM(U37:U41)
D37: =G37+M37+N37 | E37: =D37-C37 | F37: =IFERROR(D37/C37,"") | G37: =SUM(H37:L37) | N37: =SUM(O37:U37) | T37: ='2월 누계'!T37+'3월'!T37 | U37: ='2월 누계'!U37+'3월'!U37
D38: =G38+M38+N38 | E38: =D38-C38 | F38: =IFERROR(D38/C38,"") | G38: =SUM(H38:L38) | N38: =SUM(O38:U38) | T38: ='2월 누계'!T38+'3월'!T38 | U38: ='2월 누계'!U38+'3월'!U38
D39: =G39+M39+N39 | E39: =D39-C39 | F39: =IFERROR(D39/C39,"") | G39: =SUM(H39:L39) | N39: =SUM(O39:U39) | T39: ='2월 누계'!T39+'3월'!T39 | U39: ='2월 누계'!U39+'3월'!U39
D40: =G40+M40+N40 | E40: =D40-C40 | F40: =IFERROR(D40/C40,"") | G40: =SUM(H40:L40) | N40: =SUM(O40:U40) | T40: ='2월 누계'!T40+'3월'!T40 | U40: ='2월 누계'!U40+'3월'!U40
D41: =G41+M41+N41 | E41: =D41-C41 | F41: =IFERROR(D41/C41,"") | G41: =SUM(H41:L41) | N41: =SUM(O41:U41) | T41: =SUM(T42:T45) | U41: =SUM(U42:U45)
C42: =D12 | D42: =G42+M42+N42 | E42: =D42-C42 | F42: =IFERROR(D42/C42,0) | G42: =SUM(H42:L42) | N42: =SUM(O42:U42) | T42: ='2월 누계'!T42+'3월'!T42 | U42: ='2월 누계'!U42+'3월'!U42
C43: =D13 | D43: =G43+M43+N43 | E43: =D43-C43 | F43: =IFERROR(D43/C43,0) | G43: =SUM(H43:L43) | N43: =SUM(O43:U43) | T43: ='2월 누계'!T43+'3월'!T43 | U43: ='2월 누계'!U43+'3월'!U43
C44: =D14 | D44: =G44+M44+N44 | E44: =D44-C44 | F44: =IFERROR(D44/C44,0) | G44: =SUM(H44:L44) | N44: =SUM(O44:U44) | T44: ='2월 누계'!T44+'3월'!T44 | U44: ='2월 누계'!U44+'3월'!U44
C45: =D15 | D45: =G45+M45+N45 | E45: =D45-C45 | F45: =IFERROR(D45/C45,0) | G45: =SUM(H45:L45) | N45: =SUM(O45:U45) | T45: ='2월 누계'!T45+'3월'!T45 | U45: ='2월 누계'!U45+'3월'!U45
C46: =D16 | D46: =G46+M46+N46 | E46: =D46-C46 | F46: =IFERROR(D46/C46,0) | G46: =SUM(H46:L46) | H46: =SUM(H47:H58) | I46: =SUM(I47:I58) | J46: =SUM(J47:J58) | K46: =SUM(K47:K58) | L46: =SUM(L47:L58) | M46: =SUM(M47:M58) | N46: =SUM(O46:U46) | O46: =SUM(O47:O58) | P46: =SUM(P47:P58) | Q46: =SUM(Q47:Q58) | R46: =SUM(R47:R58) | S46: =SUM(S47:S58) | T46: =SUM(T47:T58) | U46: =SUM(U47:U58)
D47: =G47+M47+N47 | E47: =D47-C47 | F47: =IFERROR(D47/C47,"") | G47: =SUM(H47:L47) | N47: =SUM(O47:U47) | T47: ='2월 누계'!T47+'3월'!T47 | U47: ='2월 누계'!U47+'3월'!U47
D48: =G48+M48+N48 | E48: =D48-C48 | F48: =IFERROR(D48/C48,"") | G48: =SUM(H48:L48) | N48: =SUM(O48:U48) | T48: ='2월 누계'!T48+'3월'!T48 | U48: ='2월 누계'!U48+'3월'!U48
D49: =G49+M49+N49 | E49: =D49-C49 | F49: =IFERROR(D49/C49,"") | G49: =SUM(H49:L49) | N49: =SUM(O49:U49) | T49: ='2월 누계'!T49+'3월'!T49 | U49: ='2월 누계'!U49+'3월'!U49
D50: =G50+M50+N50 | E50: =D50-C50 | F50: =IFERROR(D50/C50,"") | G50: =SUM(H50:L50) | N50: =SUM(O50:U50) | T50: ='2월 누계'!T50+'3월'!T50 | U50: ='2월 누계'!U50+'3월'!U50
D51: =G51+M51+N51 | E51: =D51-C51 | F51: =IFERROR(D51/C51,"") | G51: =SUM(H51:L51) | N51: =SUM(O51:U51) | T51: ='2월 누계'!T51+'3월'!T51 | U51: ='2월 누계'!U51+'3월'!U51
...

Sheet 3월 누계_Diff
E5: =D5-C5 | F5: =IFERROR(D5/C5,"") | J5: =I5-H5 | K5: =IFERROR(I5/H5,"") | O5: =N5-M5 | P5: =IFERROR(N5/M5,"") | T5: =S5-R5 | U5: =IFERROR(S5/R5,"") | Y5: =X5-W5 | Z5: =IFERROR(X5/W5,"") | AD5: =AC5-AB5 | AE5: =IFERROR(AC5/AB5,"") | AI5: =AH5-AG5 | AJ5: =IFERROR(AH5/AG5,"")
E6: =D6-C6 | F6: =IFERROR(D6/C6,"") | J6: =I6-H6 | K6: =IFERROR(I6/H6,"") | O6: =N6-M6 | P6: =IFERROR(N6/M6,"") | T6: =S6-R6 | U6: =IFERROR(S6/R6,"") | Y6: =X6-W6 | Z6: =IFERROR(X6/W6,"") | AD6: =AC6-AB6 | AE6: =IFERROR(AC6/AB6,"") | AI6: =AH6-AG6 | AJ6: =IFERROR(AH6/AG6,"")
E7: =D7-C7 | F7: =IFERROR(D7/C7,"") | J7: =I7-H7 | K7: =IFERROR(I7/H7,"") | O7: =N7-M7 | P7: =IFERROR(N7/M7,"") | T7: =S7-R7 | U7: =IFERROR(S7/R7,"") | Y7: =X7-W7 | Z7: =IFERROR(X7/W7,"") | AD7: =AC7-AB7 | AE7: =IFERROR(AC7/AB7,"") | AI7: =AH7-AG7 | AJ7: =IFERROR(AH7/AG7,"")
E8: =D8-C8 | F8: =IFERROR(D8/C8,"") | J8: =I8-H8 | K8: =IFERROR(I8/H8,"") | O8: =N8-M8 | P8: =IFERROR(N8/M8,"") | T8: =S8-R8 | U8: =IFERROR(S8/R8,"") | Y8: =X8-W8 | Z8: =IFERROR(X8/W8,"") | AD8: =AC8-AB8 | AE8: =IFERROR(AC8/AB8,"") | AI8: =AH8-AG8 | AJ8: =IFERROR(AH8/AG8,"")
E9: =D9-C9 | F9: =IFERROR(D9/C9,"") | J9: =I9-H9 | K9: =IFERROR(I9/H9,"") | O9: =N9-M9 | P9: =IFERROR(N9/M9,"") | T9: =S9-R9 | U9: =IFERROR(S9/R9,"") | Y9: =X9-W9 | Z9: =IFERROR(X9/W9,"") | AD9: =AC9-AB9 | AE9: =IFERROR(AC9/AB9,"") | AI9: =AH9-AG9 | AJ9: =IFERROR(AH9/AG9,"")
E10: =D10-C10 | F10: =IFERROR(D10/C10,"") | J10: =I10-H10 | K10: =IFERROR(I10/H10,"") | O10: =N10-M10 | P10: =IFERROR(N10/M10,"") | T10: =S10-R10 | U10: =IFERROR(S10/R10,"") | Y10: =X10-W10 | Z10: =IFERROR(X10/W10,"") | AD10: =AC10-AB10 | AE10: =IFERROR(AC10/AB10,"") | AI10: =AH10-AG10 | AJ10: =IFERROR(AH10/AG10,"")
C11: =SUM(C5:C10) | D11: =SUM(D5:D10) | E11: =D11-C11 | F11: =IFERROR(D11/C11,"") | H11: =SUM(H5:H10) | I11: =SUM(I5:I10) | J11: =I11-H11 | K11: =IFERROR(I11/H11,"") | M11: =SUM(M5:M10) | N11: =SUM(N5:N10) | O11: =N11-M11 | P11: =IFERROR(N11/M11,"") | R11: =SUM(R5:R10) | S11: =SUM(S5:S10) | T11: =S11-R11 | U11: =IFERROR(S11/R11,"") | W11: =SUM(W5:W10) | X11: =SUM(X5:X10) | Y11: =X11-W11 | Z11: =IFERROR(X11/W11,"") | AB11: =SUM(AB5:AB10) | AC11: =SUM(AC5:AC10) | AD11: =AC11-AB11 | AE11: =IFERROR(AC11/AB11,"") | AG11: =SUM(AG5:AG10) | AH11: =SUM(AH5:AH10) | AI11: =AH11-AG11 | AJ11: =IFERROR(AH11/AG11,"")
E12: =D12-C12 | F12: =IFERROR(D12/C12,"") | J12: =I12-H12 | K12: =IFERROR(I12/H12,"") | O12: =N12-M12 | P12: =IFERROR(N12/M12,"") | T12: =S12-R12 | U12: =IFERROR(S12/R12,"") | Y12: =X12-W12 | Z12: =IFERROR(X12/W12,"") | AD12: =AC12-AB12 | AE12: =IFERROR(AC12/AB12,"") | AI12: =AH12-AG12 | AJ12: =IFERROR(AH12/AG12,"")
E13: =D13-C13 | F13: =IFERROR(D13/C13,"") | J13: =I13-H13 | K13: =IFERROR(I13/H13,"") | O13: =N13-M13 | P13: =IFERROR(N13/M13,"") | T13: =S13-R13 | U13: =IFERROR(S13/R13,"") | Y13: =X13-W13 | Z13: =IFERROR(X13/W13,"") | AD13: =AC13-AB13 | AE13: =IFERROR(AC13/AB13,"") | AI13: =AH13-AG13 | AJ13: =IFERROR(AH13/AG13,"")
E14: =D14-C14 | F14: =IFERROR(D14/C14,"") | J14: =I14-H14 | K14: =IFERROR(I14/H14,"") | O14: =N14-M14 | P14: =IFERROR(N14/M14,"") | T14: =S14-R14 | U14: =IFERROR(S14/R14,"") | Y14: =X14-W14 | Z14: =IFERROR(X14/W14,"") | AD14: =AC14-AB14 | AE14: =IFERROR(AC14/AB14,"") | AI14: =AH14-AG14 | AJ14: =IFERROR(AH14/AG14,"")
E15: =D15-C15 | F15: =IFERROR(D15/C15,"") | J15: =I15-H15 | K15: =IFERROR(I15/H15,"") | O15: =N15-M15 | P15: =IFERROR(N15/M15,"") | T15: =S15-R15 | U15: =IFERROR(S15/R15,"") | Y15: =X15-W15 | Z15: =IFERROR(X15/W15,"") | AD15: =AC15-AB15 | AE15: =IFERROR(AC15/AB15,"") | AI15: =AH15-AG15 | AJ15: =IFERROR(AH15/AG15,"")
E16: =D16-C16 | F16: =IFERROR(D16/C16,"") | J16: =I16-H16 | K16: =IFERROR(I16/H16,"") | O16: =N16-M16 | P16: =IFERROR(N16/M16,"") | T16: =S16-R16 | U16: =IFERROR(S16/R16,"") | Y16: =X16-W16 | Z16: =IFERROR(X16/W16,"") | AD16: =AC16-AB16 | AE16: =IFERROR(AC16/AB16,"") | AI16: =AH16-AG16 | AJ16: =IFERROR(AH16/AG16,"")
E17: =D17-C17 | F17: =IFERROR(D17/C17,"") | J17: =I17-H17 | K17: =IFERROR(I17/H17,"") | O17: =N17-M17 | P17: =IFERROR(N17/M17,"") | T17: =S17-R17 | U17: =IFERROR(S17/R17,"") | Y17: =X17-W17 | Z17: =IFERROR(X17/W17,"") | AD17: =AC17-AB17 | AE17: =IFERROR(AC17/AB17,"") | AI17: =AH17-AG17 | AJ17: =IFERROR(AH17/AG17,"")
C18: =SUM(C12:C17) | D18: =SUM(D12:D17) | E18: =D18-C18 | F18: =IFERROR(D18/C18,"") | H18: =SUM(H12:H17) | I18: =SUM(I12:I17) | J18: =I18-H18 | K18: =IFERROR(I18/H18,"") | M18: =SUM(M12:M17) | N18: =SUM(N12:N17) | O18: =N18-M18 | P18: =IFERROR(N18/M18,"") | R18: =SUM(R12:R17) | S18: =SUM(S12:S17) | T18: =S18-R18 | U18: =IFERROR(S18/R18,"") | W18: =SUM(W12:W17) | X18: =SUM(X12:X17) | Y18: =X18-W18 | Z18: =IFERROR(X18/W18,"") | AB18: =SUM(AB12:AB17) | AC18: =SUM(AC12:AC17) | AD18: =AC18-AB18 | AE18: =IFERROR(AC18/AB18,"") | AG18: =SUM(AG12:AG17) | AH18: =SUM(AH12:AH17) | AI18: =AH18-AG18 | AJ18: =IFERROR(AH18/AG18,"")
C19: =C11+C18 | D19: =D11+D18 | E19: =D19-C19 | F19: =IFERROR(D19/C19,"") | H19: =H11+H18 | I19: =I11+I18 | J19: =I19-H19 | K19: =IFERROR(I19/H19,"") | M19: =M11+M18 | N19: =N11+N18 | O19: =N19-M19 | P19: =IFERROR(N19/M19,"") | R19: =R11+R18 | S19: =S11+S18 | T19: =S19-R19 | U19: =IFERROR(S19/R19,"") | W19: =W11+W18 | X19: =X11+X18 | Y19: =X19-W19 | Z19: =IFERROR(X19/W19,"") | AB19: =AB11+AB18 | AC19: =AC11+AC18 | AD19: =AC19-AB19 | AE19: =IFERROR(AC19/AB19,"") | AG19: =AG11+AG18 | AH19: =AH11+AH18 | AI19: =AH19-AG19 | AJ19: =IFERROR(AH19/AG19,"")

Sheet 4월
D6: =G6+M6+N6 | G6: =SUM(H6:L6) | H6: =SUM(H7:H11) | I6: =SUM(I7:I11) | J6: =SUM(J7:J11) | K6: =SUM(K7:K11) | L6: =SUM(L7:L11) | M6: =SUM(M7:M11) | N6: =SUM(O6:U6) | O6: =SUM(O7:O11) | P6: =SUM(P7:P11) | Q6: =SUM(Q7:Q11) | R6: =SUM(R7:R11) | S6: =SUM(S7:S11) | T6: =SUM(T7:T11) | U6: =SUM(U7:U11)
D7: =G7+M7+N7 | G7: =SUM(H7:L7) | N7: =SUM(O7:U7)
D8: =G8+M8+N8 | G8: =SUM(H8:L8) | N8: =SUM(O8:U8)
D9: =G9+M9+N9 | G9: =SUM(H9:L9) | N9: =SUM(O9:U9)
D10: =G10+M10+N10 | G10: =SUM(H10:L10) | N10: =SUM(O10:U10)
D11: =G11+M11+N11 | G11: =SUM(H11:L11) | H11: =SUM(H12:H15) | I11: =SUM(I12:I15) | J11: =SUM(J12:J15) | K11: =SUM(K12:K15) | L11: =SUM(L12:L15) | M11: =SUM(M12:M15) | N11: =SUM(O11:U11) | O11: =SUM(O12:O15) | P11: =SUM(P12:P15) | Q11: =SUM(Q12:Q15) | R11: =SUM(R12:R15) | S11: =SUM(S12:S15) | T11: =SUM(T12:T15) | U11: =SUM(U12:U15)
D12: =G12+M12+N12 | G12: =SUM(H12:L12) | N12: =SUM(O12:U12)
D13: =G13+M13+N13 | G13: =SUM(H13:L13) | N13: =SUM(O13:U13)
D14: =G14+M14+N14 | G14: =SUM(H14:L14) | N14: =SUM(O14:U14)
D15: =G15+M15+N15 | G15: =SUM(H15:L15) | N15: =SUM(O15:U15)
D16: =G16+M16+N16 | G16: =SUM(H16:L16) | H16: =SUM(H17:H28) | I16: =SUM(I17:I28) | J16: =SUM(J17:J28) | K16: =SUM(K17:K28) | L16: =SUM(L17:L28) | M16: =SUM(M17:M28) | N16: =SUM(O16:U16) | O16: =SUM(O17:O28) | P16: =SUM(P17:P28) | Q16: =SUM(Q17:Q28) | R16: =SUM(R17:R28) | S16: =SUM(S17:S28) | T16: =SUM(T17:T28) | U16: =SUM(U17:U28)
D17: =G17+M17+N17 | G17: =SUM(H17:L17) | N17: =SUM(O17:U17)
D18: =G18+M18+N18 | G18: =SUM(H18:L18) | N18: =SUM(O18:U18)
D19: =G19+M19+N19 | G19: =SUM(H19:L19) | N19: =SUM(O19:U19)
D20: =G20+M20+N20 | G20: =SUM(H20:L20) | N20: =SUM(O20:U20)
D21: =G21+M21+N21 | G21: =SUM(H21:L21) | N21: =SUM(O21:U21)
D22: =G22+M22+N22 | G22: =SUM(H22:L22) | N22: =SUM(O22:U22)
D23: =G23+M23+N23 | G23: =SUM(H23:L23) | N23: =SUM(O23:U23)
D24: =G24+M24+N24 | G24: =SUM(H24:L24) | N24: =SUM(O24:U24)
D25: =G25+M25+N25 | G25: =SUM(H25:L25) | N25: =SUM(O25:U25)
D26: =G26+M26+N26 | G26: =SUM(H26:L26) | N26: =SUM(O26:U26)
D27: =G27+M27+N27 | G27: =SUM(H27:L27) | N27: =SUM(O27:U27)
D28: =G28+M28+N28 | G28: =SUM(H28:L28) | N28: =SUM(O28:U28)
D29: =G29+M29+N29 | G29: =SUM(H29:L29) | H29: =H6+H16 | I29: =I6+I16 | J29: =J6+J16 | K29: =K6+K16 | L29: =L6+L16 | M29: =M6+M16 | N29: =SUM(O29:U29) | O29: =O6+O16 | P29: =P6+P16 | Q29: =Q6+Q16 | R29: =R6+R16 | S29: =S6+S16 | T29: =T6+T16 | U29: =U6+U16
C36: =D6 | D36: =G36+M36+N36 | E36: =D36-C36 | F36: =IFERROR(D36/C36,0) | G36: =SUM(H36:L36) | H36: =SUM(H37:H41) | I36: =SUM(I37:I41) | J36: =SUM(J37:J41) | K36: =SUM(K37:K41) | L36: =SUM(L37:L41) | M36: =SUM(M37:M41) | N36: =SUM(O36:U36) | O36: =SUM(O37:O41) | P36: =SUM(P37:P41) | Q36: =SUM(Q37:Q41) | R36: =SUM(R37:R41) | S36: =SUM(S37:S41) | T36: =SUM(T37:T41) | U36: =SUM(U37:U41)
C37: =D7 | D37: =G37+M37+N37 | E37: =D37-C37 | F37: =IFERROR(D37/C37,0) | G37: =SUM(H37:L37) | N37: =SUM(O37:U37)
C38: =D8 | D38: =G38+M38+N38 | E38: =D38-C38 | F38: =IFERROR(D38/C38,0) | G38: =SUM(H38:L38) | N38: =SUM(O38:U38)
C39: =D9 | D39: =G39+M39+N39 | E39: =D39-C39 | F39: =IFERROR(D39/C39,0) | G39: =SUM(H39:L39) | N39: =SUM(O39:U39)
C40: =D10 | D40: =G40+M40+N40 | E40: =D40-C40 | F40: =IFERROR(D40/C40,0) | G40: =SUM(H40:L40) | N40: =SUM(O40:U40)
C41: =D11 | D41: =G41+M41+N41 | E41: =D41-C41 | F41: =IFERROR(D41/C41,0) | G41: =SUM(H41:L41) | H41: =SUM(H42:H45) | I41: =SUM(I42:I45) | J41: =SUM(J42:J45) | K41: =SUM(K42:K45) | L41: =SUM(L42:L45) | M41: =SUM(M42:M45) | N41: =SUM(O41:U41) | O41: =SUM(O42:O45) | P41: =SUM(P42:P45) | Q41: =SUM(Q42:Q45) | R41: =SUM(R42:R45) | S41: =SUM(S42:S45) | T41: =SUM(T42:T45) | U41: =SUM(U42:U45)
C42: =D12 | D42: =G42+M42+N42 | E42: =D42-C42 | F42: =IFERROR(D42/C42,0) | G42: =SUM(H42:L42) | N42: =SUM(O42:U42)
C43: =D13 | D43: =G43+M43+N43 | E43: =D43-C43 | F43: =IFERROR(D43/C43,0) | G43: =SUM(H43:L43) | N43: =SUM(O43:U43)
C44: =D14 | D44: =G44+M44+N44 | E44: =D44-C44 | F44: =IFERROR(D44/C44,0) | G44: =SUM(H44:L44) | N44: =SUM(O44:U44)
C45: =D15 | D45: =G45+M45+N45 | E45: =D45-C45 | F45: =IFERROR(D45/C45,0) | G45: =SUM(H45:L45) | N45: =SUM(O45:U45)
C46: =D16 | D46: =G46+M46+N46 | E46: =D46-C46 | F46: =IFERROR(D46/C46,0) | G46: =SUM(H46:L46) | H46: =SUM(H47:H58) | I46: =SUM(I47:I58) | J46: =SUM(J47:J58) | K46: =SUM(K47:K58) | L46: =SUM(L47:L58) | M46: =SUM(M47:M58) | N46: =SUM(O46:U46) | O46: =SUM(O47:O58) | P46: =SUM(P47:P58) | Q46: =SUM(Q47:Q58) | R46: =SUM(R47:R58) | S46: =SUM(S47:S58) | T46: =SUM(T47:T58) | U46: =SUM(U47:U58)
C47: =D17 | D47: =G47+M47+N47 | E47: =D47-C47 | F47: =IFERROR(D47/C47,0) | G47: =SUM(H47:L47) | N47: =SUM(O47:U47)
C48: =D18 | D48: =G48+M48+N48 | E48: =D48-C48 | F48: =IFERROR(D48/C48,0) | G48: =SUM(H48:L48) | N48: =SUM(O48:U48)
C49: =D19 | D49: =G49+M49+N49 | E49: =D49-C49 | F49: =IFERROR(D49/C49,0) | G49: =SUM(H49:L49) | N49: =SUM(O49:U49)
C50: =D20 | D50: =G50+M50+N50 | E50: =D50-C50 | F50: =IFERROR(D50/C50,0) | G50: =SUM(H50:L50) | N50: =SUM(O50:U50)
C51: =D21 | D51: =G51+M51+N51 | E51: =D51-C51 | F51: =IFERROR(D51/C51,0) | G51: =SUM(H51:L51) | N51: =SUM(O51:U51)
...

Sheet 4월 누계
D6: =G6+M6+N6 | G6: =SUM(H6:L6) | H6: =SUM(H7:H11) | I6: =SUM(I7:I11) | J6: =SUM(J7:J11) | K6: =SUM(K7:K11) | L6: =SUM(L7:L11) | M6: =SUM(M7:M11) | N6: =SUM(O6:U6) | O6: =SUM(O7:O11) | P6: =SUM(P7:P11) | Q6: =SUM(Q7:Q11) | R6: =SUM(R7:R11) | S6: =SUM(S7:S11) | T6: =SUM(T7:T11) | U6: =SUM(U7:U11)
D7: =G7+M7+N7 | G7: =SUM(H7:L7) | H7: ='3월 누계'!H7+'4월'!H7 | I7: ='3월 누계'!I7+'4월'!I7 | J7: ='3월 누계'!J7+'4월'!J7 | K7: ='3월 누계'!K7+'4월'!K7 | L7: ='3월 누계'!L7+'4월'!L7 | M7: ='3월 누계'!M7+'4월'!M7 | N7: =SUM(O7:U7) | O7: ='3월 누계'!O7+'4월'!O7 | P7: ='3월 누계'!P7+'4월'!P7 | Q7: ='3월 누계'!Q7+'4월'!Q7 | R7: ='3월 누계'!R7+'4월'!R7 | S7: ='3월 누계'!S7+'4월'!S7 | T7: ='3월 누계'!T7+'4월'!T7 | U7: ='3월 누계'!U7+'4월'!U7
D8: =G8+M8+N8 | G8: =SUM(H8:L8) | H8: ='3월 누계'!H8+'4월'!H8 | I8: ='3월 누계'!I8+'4월'!I8 | J8: ='3월 누계'!J8+'4월'!J8 | K8: ='3월 누계'!K8+'4월'!K8 | L8: ='3월 누계'!L8+'4월'!L8 | M8: ='3월 누계'!M8+'4월'!M8 | N8: =SUM(O8:U8) | O8: ='3월 누계'!O8+'4월'!O8 | P8: ='3월 누계'!P8+'4월'!P8 | Q8: ='3월 누계'!Q8+'4월'!Q8 | R8: ='3월 누계'!R8+'4월'!R8 | S8: ='3월 누계'!S8+'4월'!S8 | T8: ='3월 누계'!T8+'4월'!T8 | U8: ='3월 누계'!U8+'4월'!U8
D9: =G9+M9+N9 | G9: =SUM(H9:L9) | H9: ='3월 누계'!H9+'4월'!H9 | I9: ='3월 누계'!I9+'4월'!I9 | J9: ='3월 누계'!J9+'4월'!J9 | K9: ='3월 누계'!K9+'4월'!K9 | L9: ='3월 누계'!L9+'4월'!L9 | M9: ='3월 누계'!M9+'4월'!M9 | N9: =SUM(O9:U9) | O9: ='3월 누계'!O9+'4월'!O9 | P9: ='3월 누계'!P9+'4월'!P9 | Q9: ='3월 누계'!Q9+'4월'!Q9 | R9: ='3월 누계'!R9+'4월'!R9 | S9: ='3월 누계'!S9+'4월'!S9 | T9: ='3월 누계'!T9+'4월'!T9 | U9: ='3월 누계'!U9+'4월'!U9
D10: =G10+M10+N10 | G10: =SUM(H10:L10) | H10: ='3월 누계'!H10+'4월'!H10 | I10: ='3월 누계'!I10+'4월'!I10 | J10: ='3월 누계'!J10+'4월'!J10 | K10: ='3월 누계'!K10+'4월'!K10 | L10: ='3월 누계'!L10+'4월'!L10 | M10: ='3월 누계'!M10+'4월'!M10 | N10: =SUM(O10:U10) | O10: ='3월 누계'!O10+'4월'!O10 | P10: ='3월 누계'!P10+'4월'!P10 | Q10: ='3월 누계'!Q10+'4월'!Q10 | R10: ='3월 누계'!R10+'4월'!R10 | S10: ='3월 누계'!S10+'4월'!S10 | T10: ='3월 누계'!T10+'4월'!T10 | U10: ='3월 누계'!U10+'4월'!U10
D11: =G11+M11+N11 | G11: =SUM(H11:L11) | H11: =SUM(H12:H15) | I11: =SUM(I12:I15) | J11: =SUM(J12:J15) | K11: =SUM(K12:K15) | L11: =SUM(L12:L15) | M11: =SUM(M12:M15) | N11: =SUM(O11:U11) | O11: =SUM(O12:O15) | P11: =SUM(P12:P15) | Q11: =SUM(Q12:Q15) | R11: =SUM(R12:R15) | S11: =SUM(S12:S15) | T11: =SUM(T12:T15) | U11: =SUM(U12:U15)
D12: =G12+M12+N12 | G12: =SUM(H12:L12) | H12: ='3월 누계'!H12+'4월'!H12 | I12: ='3월 누계'!I12+'4월'!I12 | J12: ='3월 누계'!J12+'4월'!J12 | K12: ='3월 누계'!K12+'4월'!K12 | L12: ='3월 누계'!L12+'4월'!L12 | M12: ='3월 누계'!M12+'4월'!M12 | N12: =SUM(O12:U12) | O12: ='3월 누계'!O12+'4월'!O12 | P12: ='3월 누계'!P12+'4월'!P12 | Q12: ='3월 누계'!Q12+'4월'!Q12 | R12: ='3월 누계'!R12+'4월'!R12 | S12: ='3월 누계'!S12+'4월'!S12 | T12: ='3월 누계'!T12+'4월'!T12 | U12: ='3월 누계'!U12+'4월'!U12
D13: =G13+M13+N13 | G13: =SUM(H13:L13) | H13: ='3월 누계'!H13+'4월'!H13 | I13: ='3월 누계'!I13+'4월'!I13 | J13: ='3월 누계'!J13+'4월'!J13 | K13: ='3월 누계'!K13+'4월'!K13 | L13: ='3월 누계'!L13+'4월'!L13 | M13: ='3월 누계'!M13+'4월'!M13 | N13: =SUM(O13:U13) | O13: ='3월 누계'!O13+'4월'!O13 | P13: ='3월 누계'!P13+'4월'!P13 | Q13: ='3월 누계'!Q13+'4월'!Q13 | R13: ='3월 누계'!R13+'4월'!R13 | S13: ='3월 누계'!S13+'4월'!S13 | T13: ='3월 누계'!T13+'4월'!T13 | U13: ='3월 누계'!U13+'4월'!U13
D14: =G14+M14+N14 | G14: =SUM(H14:L14) | H14: ='3월 누계'!H14+'4월'!H14 | I14: ='3월 누계'!I14+'4월'!I14 | J14: ='3월 누계'!J14+'4월'!J14 | K14: ='3월 누계'!K14+'4월'!K14 | L14: ='3월 누계'!L14+'4월'!L14 | M14: ='3월 누계'!M14+'4월'!M14 | N14: =SUM(O14:U14) | O14: ='3월 누계'!O14+'4월'!O14 | P14: ='3월 누계'!P14+'4월'!P14 | Q14: ='3월 누계'!Q14+'4월'!Q14 | R14: ='3월 누계'!R14+'4월'!R14 | S14: ='3월 누계'!S14+'4월'!S14 | T14: ='3월 누계'!T14+'4월'!T14 | U14: ='3월 누계'!U14+'4월'!U14
D15: =G15+M15+N15 | G15: =SUM(H15:L15) | H15: ='3월 누계'!H15+'4월'!H15 | I15: ='3월 누계'!I15+'4월'!I15 | J15: ='3월 누계'!J15+'4월'!J15 | K15: ='3월 누계'!K15+'4월'!K15 | L15: ='3월 누계'!L15+'4월'!L15 | M15: ='3월 누계'!M15+'4월'!M15 | N15: =SUM(O15:U15) | O15: ='3월 누계'!O15+'4월'!O15 | P15: ='3월 누계'!P15+'4월'!P15 | Q15: ='3월 누계'!Q15+'4월'!Q15 | R15: ='3월 누계'!R15+'4월'!R15 | S15: ='3월 누계'!S15+'4월'!S15 | T15: ='3월 누계'!T15+'4월'!T15 | U15: ='3월 누계'!U15+'4월'!U15
D16: =G16+M16+N16 | G16: =SUM(H16:L16) | H16: =SUM(H17:H28) | I16: =SUM(I17:I28) | J16: =SUM(J17:J28) | K16: =SUM(K17:K28) | L16: =SUM(L17:L28) | M16: =SUM(M17:M28) | N16: =SUM(O16:U16) | O16: =SUM(O17:O28) | P16: =SUM(P17:P28) | Q16: =SUM(Q17:Q28) | R16: =SUM(R17:R28) | S16: =SUM(S17:S28) | T16: =SUM(T17:T28) | U16: =SUM(U17:U28)
D17: =G17+M17+N17 | G17: =SUM(H17:L17) | H17: ='3월 누계'!H17+'4월'!H17 | I17: ='3월 누계'!I17+'4월'!I17 | J17: ='3월 누계'!J17+'4월'!J17 | K17: ='3월 누계'!K17+'4월'!K17 | L17: ='3월 누계'!L17+'4월'!L17 | M17: ='3월 누계'!M17+'4월'!M17 | N17: =SUM(O17:U17) | O17: ='3월 누계'!O17+'4월'!O17 | P17: ='3월 누계'!P17+'4월'!P17 | Q17: ='3월 누계'!Q17+'4월'!Q17 | R17: ='3월 누계'!R17+'4월'!R17 | S17: ='3월 누계'!S17+'4월'!S17 | T17: ='3월 누계'!T17+'4월'!T17 | U17: ='3월 누계'!U17+'4월'!U17
